Workbook

Sheet FY26-27
B1: FY26-27 Budgeted vs Actual MIS
B2: Food Matters Group | FY26-27
C3: Total with HO (Amount) | G3: HO (Amount) | K3: Outlets Total | O3: Table Total | S3: Iktara | W3: Mg St Colaba | AA3: Mg St LP | AE3: Mg St Bandra | AI3: MSK Events | AM3: MSBC | AQ3: Kaspers | AU3: MSBC Andheri | AY3: MSBC Dahisar | BC3: MSBC Juhu/Goregaon | BG3: MSBC Loudmouth
C4: Amount | D4: %age | E4: Budgeted | F4: %age | G4: Actual | H4: %age | I4: Budgeted | J4: %age | K4: Amount | L4: %age | M4: Budgeted | N4: %age | O4: Amount | P4: %age | Q4: Budgeted | R4: %age | S4: Amount | T4: %age | U4: Budgeted | V4: %age | W4: Amount | X4: %age | Y4: Budgeted | Z4: %age | AA4: Amount | AB4: %age | AC4: Budgeted | AD4: %age | AE4: Amount | AF4: %age | AG4: Budgeted | AH4: %age | AI4: Amount | AJ4: %age | AK4: Budgeted | AL4: %age | AM4: Amount | AN4: %age | AO4: Budgeted | AP4: %age | AQ4: Amount | AR4: %age | AS4: Budgeted | AT4: %age | AU4: Amount | AV4: %age | AW4: Budgeted | AX4: %age | AY4: Amount | AZ4: %age | BA4: Budgeted | BB4: %age | BC4: Amount | BD4: %age | BE4: Budgeted | BF4: %age | BG4: Amount | BH4: %age | BI4: Budgeted | BJ4: %age
B5: Beverage | C5: =G5+K5 -> 11608400 | D5: =C5/$C$10 -> 0.078003476 | E5: =I5+M5 -> 0 | F5: =E5/E$10 -> #DIV/0! | G5: ='Q1 FY26-27'!G5 -> 0 | I5: ='Q1 FY26-27'!I5 -> 0 | K5: =O5+S5+W5+AA5+AE5+AI5+AM5+AQ5+AU5+AY5+BC5+BG5 -> 11608400 | L5: =K5/$K$10 -> 0.078003476 | M5: =Q5+U5+Y5+AC5+AG5+AK5+AO5 -> 0 | N5: =M5/M$10 -> #DIV/0! | O5: ='Q1 FY26-27'!O5 -> 2407580 | P5: =O5/O$10 -> 0.058815722 | Q5: ='Q1 FY26-27'!Q5 -> 0 | R5: =Q5/Q$10 -> #DIV/0! | S5: ='Q1 FY26-27'!S5 -> 0 | T5: =S5/S$10 -> 0 | U5: ='Q1 FY26-27'!U5 -> 0 | V5: =U5/U$10 -> #DIV/0! | W5: ='Q1 FY26-27'!W5 -> 2398144 | X5: =W5/W$10 -> 0.094851748 | Y5: ='Q1 FY26-27'!Y5 -> 0 | Z5: =Y5/Y$10 -> #DIV/0! | AA5: ='Q1 FY26-27'!AA5 -> 2390099.8 | AB5: =AA5/AA$10 -> 0.12483768 | AC5: ='Q1 FY26-27'!AC5 -> 0 | AD5: =AC5/AC$10 -> #DIV/0! | AE5: ='Q1 FY26-27'!AE5 -> 3237788.5 | AF5: =AE5/AE$10 -> 0.094581636 | AG5: ='Q1 FY26-27'!AG5 -> 0 | AH5: =AG5/AG$10 -> #DIV/0! | AI5: ='Q1 FY26-27'!AI5 -> 0 | AJ5: =AI5/AI$10 -> #DIV/0! | AK5: ='Q1 FY26-27'!AK5 -> 0 | AL5: =AK5/AK$10 -> #DIV/0! | AM5: ='Q1 FY26-27'!AM5 -> 0 | AN5: =AM5/AM$10 -> 0 | AO5: ='Q1 FY26-27'!AO5 -> 0 | AP5: =AO5/AO$10 -> #DIV/0! | AQ5: ='Q1 FY26-27'!AQ5 -> 1174787.5 | AR5: =AQ5/AQ$10 -> 0.048653213 | AS5: ='Q1 FY26-27'!AS5 -> 0 | AU5: 0 | AV5: =AU5/AU$10 -> 0 | AW5: ='Q1 FY26-27'!AW5 -> 0 | AY5: ='Q1 FY26-27'!AY5 -> 0 | BA5: ='Q1 FY26-27'!BA5 -> 0 | BC5: ='Q1 FY26-27'!BC5 -> 0 | BE5: ='Q1 FY26-27'!BE5 -> 0 | BG5: ='Q1 FY26-27'!BG5 -> 0 | BI5: ='Q1 FY26-27'!BI5 -> 0
B6: Liquor | C6: =G6+K6 -> 24020516 | D6: =C6/$C$10 -> 0.16140758 | E6: =I6+M6 -> 0 | F6: =E6/E$10 -> #DIV/0! | G6: ='Q1 FY26-27'!G6 -> 0 | I6: ='Q1 FY26-27'!I6 -> 0 | K6: =O6+S6+W6+AA6+AE6+AI6+AM6+AQ6+AU6+AY6+BC6+BG6 -> 24020516 | L6: =K6/$K$10 -> 0.16140758 | M6: =Q6+U6+Y6+AC6+AG6+AK6+AO6 -> 0 | N6: =M6/M$10 -> #DIV/0! | O6: ='Q1 FY26-27'!O6 -> 9818016 | P6: =O6/O$10 -> 0.23984819 | Q6: ='Q1 FY26-27'!Q6 -> 0 | R6: =Q6/Q$10 -> #DIV/0! | S6: ='Q1 FY26-27'!S6 -> 0 | T6: =S6/S$10 -> 0 | U6: ='Q1 FY26-27'!U6 -> 0 | V6: =U6/U$10 -> #DIV/0! | W6: ='Q1 FY26-27'!W6 -> 1505040 | X6: =W6/W$10 -> 0.059527566 | Y6: ='Q1 FY26-27'!Y6 -> 0 | Z6: =Y6/Y$10 -> #DIV/0! | AA6: ='Q1 FY26-27'!AA6 -> 0 | AB6: =AA6/AA$10 -> 0 | AC6: ='Q1 FY26-27'!AC6 -> 0 | AD6: =AC6/AC$10 -> #DIV/0! | AE6: ='Q1 FY26-27'!AE6 -> 4194442.5 | AF6: =AE6/AE$10 -> 0.12252722 | AG6: ='Q1 FY26-27'!AG6 -> 0 | AH6: =AG6/AG$10 -> #DIV/0! | AI6: ='Q1 FY26-27'!AI6 -> 0 | AJ6: =AI6/AI$10 -> #DIV/0! | AK6: ='Q1 FY26-27'!AK6 -> 0 | AL6: =AK6/AK$10 -> #DIV/0! | AM6: ='Q1 FY26-27'!AM6 -> 0 | AN6: =AM6/AM$10 -> 0 | AO6: ='Q1 FY26-27'!AO6 -> 0 | AP6: =AO6/AO$10 -> #DIV/0! | AQ6: ='Q1 FY26-27'!AQ6 -> 8503017.5 | AR6: =AQ6/AQ$10 -> 0.35214804 | AS6: ='Q1 FY26-27'!AS6 -> 0 | AU6: 0 | AV6: =AU6/AU$10 -> 0 | AW6: ='Q1 FY26-27'!AW6 -> 0 | AY6: ='Q1 FY26-27'!AY6 -> 0 | BA6: ='Q1 FY26-27'!BA6 -> 0 | BC6: ='Q1 FY26-27'!BC6 -> 0 | BE6: ='Q1 FY26-27'!BE6 -> 0 | BG6: ='Q1 FY26-27'!BG6 -> 0 | BI6: ='Q1 FY26-27'!BI6 -> 0
B7: Food | C7: =G7+K7 -> 1.0826025e+08 | D7: =C7/$C$10 -> 0.72746255 | E7: =I7+M7 -> 0 | F7: =E7/E$10 -> #DIV/0! | G7: ='Q1 FY26-27'!G7 -> 0 | I7: ='Q1 FY26-27'!I7 -> 0 | K7: =O7+S7+W7+AA7+AE7+AI7+AM7+AQ7+AU7+AY7+BC7+BG7 -> 1.0826025e+08 | L7: =K7/$K$10 -> 0.72746255 | M7: =Q7+U7+Y7+AC7+AG7+AK7+AO7 -> 0 | N7: =M7/M$10 -> #DIV/0! | O7: ='Q1 FY26-27'!O7 -> 26989559 | P7: =O7/O$10 -> 0.65933859 | Q7: ='Q1 FY26-27'!Q7 -> 0 | R7: =Q7/Q$10 -> #DIV/0! | S7: ='Q1 FY26-27'!S7 -> 1667248 | T7: =S7/S$10 -> 1 | U7: ='Q1 FY26-27'!U7 -> 0 | V7: =U7/U$10 -> #DIV/0! | W7: ='Q1 FY26-27'!W7 -> 20658266 | X7: =W7/W$10 -> 0.81707883 | Y7: ='Q1 FY26-27'!Y7 -> 0 | Z7: =Y7/Y$10 -> #DIV/0! | AA7: ='Q1 FY26-27'!AA7 -> 16390588 | AB7: =AA7/AA$10 -> 0.85609941 | AC7: ='Q1 FY26-27'!AC7 -> 0 | AD7: =AC7/AC$10 -> #DIV/0! | AE7: ='Q1 FY26-27'!AE7 -> 25758068 | AF7: =AE7/AE$10 -> 0.75243959 | AG7: ='Q1 FY26-27'!AG7 -> 0 | AH7: =AG7/AG$10 -> #DIV/0! | AI7: ='Q1 FY26-27'!AI7 -> 0 | AJ7: =AI7/AI$10 -> #DIV/0! | AK7: ='Q1 FY26-27'!AK7 -> 0 | AL7: =AK7/AK$10 -> #DIV/0! | AM7: ='Q1 FY26-27'!AM7 -> 970993.82 | AN7: =AM7/AM$10 -> 1 | AO7: ='Q1 FY26-27'!AO7 -> 0 | AP7: =AO7/AO$10 -> #DIV/0! | AQ7: ='Q1 FY26-27'!AQ7 -> 13386680 | AR7: =AQ7/AQ$10 -> 0.55440236 | AS7: ='Q1 FY26-27'!AS7 -> 0 | AU7: ='Q1 FY26-27'!AU7 -> 666826.99 | AV7: =AU7/AU$10 -> 1 | AW7: ='Q1 FY26-27'!AW7 -> 0 | AY7: ='Q1 FY26-27'!AY7 -> 228077.89 | BA7: ='Q1 FY26-27'!BA7 -> 0 | BC7: ='Q1 FY26-27'!BC7 -> 306961.08 | BE7: ='Q1 FY26-27'!BE7 -> 0 | BG7: ='Q1 FY26-27'!BG7 -> 1236985 | BI7: ='Q1 FY26-27'!BI7 -> 0
B8: Service Charge | C8: =G8+K8 -> 4894605 | D8: =C8/$C$10 -> 0.03288965 | E8: =I8+M8 -> 0 | F8: =E8/E$10 -> #DIV/0! | G8: ='Q1 FY26-27'!G8 -> 0 | I8: ='Q1 FY26-27'!I8 -> 0 | K8: =O8+S8+W8+AA8+AE8+AI8+AM8+AQ8+AU8+AY8+BC8+BG8 -> 4894605 | L8: =K8/$K$10 -> 0.03288965 | M8: =Q8+U8+Y8+AC8+AG8+AK8+AO8 -> 0 | N8: =M8/M$10 -> #DIV/0! | O8: ='Q1 FY26-27'!O8 -> 1719138 | P8: =O8/O$10 -> 0.041997501 | Q8: ='Q1 FY26-27'!Q8 -> 0 | R8: =Q8/Q$10 -> #DIV/0! | S8: ='Q1 FY26-27'!S8 -> 0 | T8: =S8/S$10 -> 0 | U8: ='Q1 FY26-27'!U8 -> 0 | V8: =U8/U$10 -> #DIV/0! | W8: ='Q1 FY26-27'!W8 -> 721626 | X8: =W8/W$10 -> 0.028541859 | Y8: ='Q1 FY26-27'!Y8 -> 0 | Z8: =Y8/Y$10 -> #DIV/0! | AA8: ='Q1 FY26-27'!AA8 -> 356972.05 | AB8: =AA8/AA$10 -> 0.018645064 | AC8: ='Q1 FY26-27'!AC8 -> 0 | AD8: =AC8/AC$10 -> #DIV/0! | AE8: ='Q1 FY26-27'!AE8 -> 1028709 | AF8: =AE8/AE$10 -> 0.030050444 | AG8: ='Q1 FY26-27'!AG8 -> 0 | AH8: =AG8/AG$10 -> #DIV/0! | AI8: ='Q1 FY26-27'!AI8 -> 0 | AJ8: =AI8/AI$10 -> #DIV/0! | AK8: ='Q1 FY26-27'!AK8 -> 0 | AL8: =AK8/AK$10 -> #DIV/0! | AM8: ='Q1 FY26-27'!AM8 -> 0 | AN8: =AM8/AM$10 -> 0 | AO8: ='Q1 FY26-27'!AO8 -> 0 | AP8: =AO8/AO$10 -> #DIV/0! | AQ8: ='Q1 FY26-27'!AQ8 -> 1068160 | AR8: =AQ8/AQ$10 -> 0.04423729 | AS8: ='Q1 FY26-27'!AS8 -> 0 | AU8: 0 | AV8: =AU8/AU$10 -> 0 | AW8: ='Q1 FY26-27'!AW8 -> 0 | AY8: ='Q1 FY26-27'!AY8 -> 0 | BA8: ='Q1 FY26-27'!BA8 -> 0 | BC8: ='Q1 FY26-27'!BC8 -> 0 | BE8: ='Q1 FY26-27'!BE8 -> 0 | BG8: ='Q1 FY26-27'!BG8 -> 0 | BI8: ='Q1 FY26-27'!BI8 -> 0
B9: Scrap Sales | C9: =G9+K9 -> 35231 | D9: =C9/$C$10 -> 0.00023673724 | E9: =I9+M9 -> 0 | F9: =E9/E$10 -> #DIV/0! | G9: ='Q1 FY26-27'!G9 -> 0 | I9: ='Q1 FY26-27'!I9 -> 0 | K9: =O9+S9+W9+AA9+AE9+AI9+AM9+AQ9+AU9+AY9+BC9+BG9 -> 35231 | L9: =K9/$K$10 -> 0.00023673724 | M9: =Q9+U9+Y9+AC9+AG9+AK9+AO9 -> 0 | N9: =M9/M$10 -> #DIV/0! | O9: ='Q1 FY26-27'!O9 -> 0 | P9: =O9/O$10 -> 0 | Q9: ='Q1 FY26-27'!Q9 -> 0 | R9: =Q9/Q$10 -> #DIV/0! | S9: ='Q1 FY26-27'!S9 -> 0 | T9: =S9/S$10 -> 0 | U9: ='Q1 FY26-27'!U9 -> 0 | V9: =U9/U$10 -> #DIV/0! | W9: ='Q1 FY26-27'!W9 -> 0 | X9: =W9/W$10 -> 0 | Y9: ='Q1 FY26-27'!Y9 -> 0 | Z9: =Y9/Y$10 -> #DIV/0! | AA9: ='Q1 FY26-27'!AA9 -> 8000 | AB9: =AA9/AA$10 -> 0.00041784927 | AC9: ='Q1 FY26-27'!AC9 -> 0 | AD9: =AC9/AC$10 -> #DIV/0! | AE9: ='Q1 FY26-27'!AE9 -> 13731 | AF9: =AE9/AE$10 -> 0.00040110725 | AG9: ='Q1 FY26-27'!AG9 -> 0 | AH9: =AG9/AG$10 -> #DIV/0! | AI9: ='Q1 FY26-27'!AI9 -> 0 | AJ9: =AI9/AI$10 -> #DIV/0! | AK9: ='Q1 FY26-27'!AK9 -> 0 | AL9: =AK9/AK$10 -> #DIV/0! | AM9: ='Q1 FY26-27'!AM9 -> 0 | AN9: =AM9/AM$10 -> 0 | AO9: ='Q1 FY26-27'!AO9 -> 0 | AP9: =AO9/AO$10 -> #DIV/0! | AQ9: ='Q1 FY26-27'!AQ9 -> 13500 | AR9: =AQ9/AQ$10 -> 0.00055909547 | AS9: ='Q1 FY26-27'!AS9 -> 0 | AU9: 0 | AV9: =AU9/AU$10 -> 0 | AW9: ='Q1 FY26-27'!AW9 -> 0 | AY9: ='Q1 FY26-27'!AY9 -> 0 | BA9: ='Q1 FY26-27'!BA9 -> 0 | BC9: ='Q1 FY26-27'!BC9 -> 0 | BE9: ='Q1 FY26-27'!BE9 -> 0 | BG9: ='Q1 FY26-27'!BG9 -> 0 | BI9: ='Q1 FY26-27'!BI9 -> 0
B10: Total Sales Revenue | C10: =SUM(C5:C9) -> 1.4881901e+08 | D10: =C10/C10 -> 1 | E10: =SUM(E5:E9) -> 0 | F10: =E10/E10 -> #DIV/0! | G10: =SUM(G5:G9) -> 0 | I10: =SUM(I5:I9) -> 0 | K10: =SUM(K5:K9) -> 1.4881901e+08 | L10: =K10/K10 -> 1 | M10: =SUM(M5:M9) -> 0 | N10: =M10/M10 -> #DIV/0! | O10: =SUM(O5:O9) -> 40934293 | Q10: =SUM(Q5:Q9) -> 0 | S10: =SUM(S5:S9) -> 1667248 | U10: =SUM(U5:U8) -> 0 | W10: =SUM(W5:W9) -> 25283076 | Y10: =SUM(Y5:Y8) -> 0 | AA10: =SUM(AA5:AA9) -> 19145660 | AC10: =SUM(AC5:AC8) -> 0 | AE10: =SUM(AE5:AE9) -> 34232739 | AG10: =SUM(AG5:AG8) -> 0 | AI10: =SUM(AI5:AI9) -> 0 | AK10: =SUM(AK5:AK9) -> 0 | AM10: =SUM(AM5:AM9) -> 970993.82 | AO10: =SUM(AO5:AO8) -> 0 | AQ10: =SUM(AQ5:AQ9) -> 24146144 | AS10: ='Q1 FY26-27'!AS10 -> 0 | AU10: =SUM(AU5:AU8) -> 666826.99 | AW10: =SUM(AW5:AW8) -> 0 | AY10: =SUM(AY5:AY8) -> 228077.89 | BA10: =SUM(BA5:BA8) -> 0 | BC10: =SUM(BC5:BC8) -> 306961.08 | BE10: =SUM(BE5:BE8) -> 0 | BG10: =SUM(BG5:BG8) -> 1236985 | BI10: =SUM(BI5:BI8) -> 0
B11: Average /Month | C11: =C10/12 -> 12401584 | E11: =E10/12 -> 0 | G11: ='Q1 FY26-27'!G11 -> 0 | I11: ='Q1 FY26-27'!I11 -> 0 | O11: ='Q1 FY26-27'!O11 -> 0 | S11: =S10/12 -> 138937.33 | U11: =U10/12 -> 0 | W11: =W10/12 -> 2106923 | Y11: =Y10/12 -> 0 | AA11: =AA10/12 -> 1595471.7 | AE11: =AE10/12 -> 2852728.3 | AG11: ='Q1 FY26-27'!AG11 -> 0 | AI11: ='Q1 FY26-27'!AI11 -> 0 | AK11: ='Q1 FY26-27'!AK11 -> 0 | AM11: =AM10/12 -> 80916.152 | AO11: ='Q1 FY26-27'!AO11 -> 0 | AQ11: =AQ10/4.5 -> 5365809.9 | AS11: ='Q1 FY26-27'!AS11 -> 0 | AU11: 0 | AW11: 0 | AY11: 0 | BA11: 0 | BC11: 0 | BE11: 0 | BG11: 0 | BI11: 0
B12: COGS | C12: =G12+K12 -> 55832434 | D12: =C12/$C$10 -> 0.37517005 | E12: =I12+M12 -> 0 | F12: =E12/E$10 -> #DIV/0! | G12: ='Q1 FY26-27'!G12 -> 0 | H12: =G12/$C$10 -> 0 | I12: ='Q1 FY26-27'!I12 -> 0 | J12: =I12/$C$10 -> 0 | K12: =O12+S12+W12+AA12+AE12+AI12+AM12+AQ12+AU12+AY12+BC12+BG12 -> 55832434 | L12: =K12/$K$10 -> 0.37517005 | M12: =Q12+U12+Y12+AC12+AG12+AK12+AO12 -> 0 | N12: =M12/M$10 -> #DIV/0! | O12: ='Q1 FY26-27'!O12 -> 14259873 | P12: =O12/O$10 -> 0.34836006 | Q12: ='Q1 FY26-27'!Q12 -> 0 | R12: =Q12/Q$10 -> #DIV/0! | S12: ='Q1 FY26-27'!S12 -> 573413.45 | T12: =S12/S$10 -> 0.34392811 | U12: ='Q1 FY26-27'!U12 -> 0 | V12: =U12/U$10 -> #DIV/0! | W12: ='Q1 FY26-27'!W12 -> 9869489.7 | X12: =W12/W$10 -> 0.39035952 | Y12: ='Q1 FY26-27'!Y12 -> 0 | Z12: =Y12/Y$10 -> #DIV/0! | AA12: ='Q1 FY26-27'!AA12 -> 6943290.1 | AB12: =AA12/AA$10 -> 0.36265609 | AC12: ='Q1 FY26-27'!AC12 -> 0 | AD12: =AC12/AC$10 -> #DIV/0! | AE12: ='Q1 FY26-27'!AE12 -> 11423138 | AF12: =AE12/AE$10 -> 0.33369043 | AG12: ='Q1 FY26-27'!AG12 -> 0 | AH12: =AG12/AG$10 -> #DIV/0! | AI12: ='Q1 FY26-27'!AI12 -> 0 | AJ12: =AI12/AI$10 -> #DIV/0! | AK12: ='Q1 FY26-27'!AK12 -> 0 | AL12: =AK12/AK$10 -> #DIV/0! | AM12: ='Q1 FY26-27'!AM12 -> 1697483.5 | AN12: =AM12/AM$10 -> 1.7481919 | AO12: ='Q1 FY26-27'!AO12 -> 0 | AP12: =AO12/AO$10 -> #DIV/0! | AQ12: ='Q1 FY26-27'!AQ12 -> 9435973 | AR12: =AQ12/AQ$10 -> 0.39078591 | AS12: ='Q1 FY26-27'!AS12 -> 0 | AU12: ='Q1 FY26-27'!AU12 -> 438745.12 | AV12: =AU12/AU$10 -> 0.65795945 | AW12: ='Q1 FY26-27'!AW12 -> 0 | AY12: ='Q1 FY26-27'!AY12 -> 339203.01 | BA12: ='Q1 FY26-27'!BA12 -> 0 | BC12: ='Q1 FY26-27'!BC12 -> 495419.73 | BE12: ='Q1 FY26-27'!BE12 -> 0 | BG12: ='Q1 FY26-27'!BG12 -> 356406.24 | BI12: ='Q1 FY26-27'!BI12 -> 0
B13: Packaging Cost | C13: =G13+K13 -> 1899950.2 | D13: =C13/$C$10 -> 0.012766852 | E13: =I13+M13 -> 0 | F13: =E13/E$10 -> #DIV/0! | G13: ='Q1 FY26-27'!G13 -> 0 | I13: ='Q1 FY26-27'!I13 -> 0 | K13: =O13+S13+W13+AA13+AE13+AI13+AM13+AQ13+AU13+AY13+BC13+BG13 -> 1899950.2 | L13: =K13/$K$10 -> 0.012766852 | M13: =Q13+U13+Y13+AC13+AG13+AK13+AO13 -> 0 | N13: =M13/M$10 -> #DIV/0! | O13: ='Q1 FY26-27'!O13 -> 106548 | P13: =O13/O$10 -> 0.0026029032 | Q13: ='Q1 FY26-27'!Q13 -> 0 | R13: =Q13/Q$10 -> #DIV/0! | S13: ='Q1 FY26-27'!S13 -> 73214 | T13: =S13/S$10 -> 0.043913083 | U13: ='Q1 FY26-27'!U13 -> 0 | V13: =U13/U$10 -> #DIV/0! | W13: ='Q1 FY26-27'!W13 -> 366401.4 | X13: =W13/W$10 -> 0.014491963 | Y13: ='Q1 FY26-27'!Y13 -> 0 | Z13: =Y13/Y$10 -> #DIV/0! | AA13: ='Q1 FY26-27'!AA13 -> 442124 | AB13: =AA13/AA$10 -> 0.023092649 | AC13: ='Q1 FY26-27'!AC13 -> 0 | AD13: =AC13/AC$10 -> #DIV/0! | AE13: ='Q1 FY26-27'!AE13 -> 512245.02 | AF13: =AE13/AE$10 -> 0.0149636 | AG13: ='Q1 FY26-27'!AG13 -> 0 | AH13: =AG13/AG$10 -> #DIV/0! | AI13: ='Q1 FY26-27'!AI13 -> 1030 | AJ13: =AI13/AI$10 -> #DIV/0! | AK13: ='Q1 FY26-27'!AK13 -> 0 | AL13: =AK13/AK$10 -> #DIV/0! | AM13: ='Q1 FY26-27'!AM13 -> 203076.5 | AN13: =AM13/AM$10 -> 0.20914294 | AO13: ='Q1 FY26-27'!AO13 -> 0 | AP13: =AO13/AO$10 -> #DIV/0! | AQ13: ='Q1 FY26-27'!AQ13 -> 85375.3 | AR13: =AQ13/AQ$10 -> 0.0035357736 | AS13: ='Q1 FY26-27'!AS13 -> 0 | AU13: ='Q1 FY26-27'!AU13 -> 8383 | AV13: =AU13/AU$10 -> 0.012571477 | AW13: ='Q1 FY26-27'!AW13 -> 0 | AY13: ='Q1 FY26-27'!AY13 -> 9422 | BA13: ='Q1 FY26-27'!BA13 -> 0 | BC13: ='Q1 FY26-27'!BC13 -> 5647 | BE13: ='Q1 FY26-27'!BE13 -> 0 | BG13: ='Q1 FY26-27'!BG13 -> 86484 | BI13: ='Q1 FY26-27'!BI13 -> 0
B14: Total COGS & Packaging | C14: =SUM(C12:C13) -> 57732384 | D14: =C14/C10 -> 0.3879369 | E14: =E12+E13 -> 0 | F14: =E14/E$10 -> #DIV/0! | G14: ='Q1 FY26-27'!G14 -> 0 | H14: =G14/C10 -> 0 | I14: ='Q1 FY26-27'!I14 -> 0 | J14: =I14/E10 -> #DIV/0! | K14: ='Q1 FY26-27'!K14 -> 57732384 | L14: =K14/K10 -> 0.3879369 | M14: =M12+M13 -> 0 | N14: =M14/M$10 -> #DIV/0! | O14: ='Q1 FY26-27'!O14 -> 14366421 | P14: =O14/O$10 -> 0.35096296 | Q14: =SUM(Q12:Q13) -> 0 | R14: =Q14/Q$10 -> #DIV/0! | S14: =SUM(S12:S13) -> 646627.45 | U14: =SUM(U12:U13) -> 0 | V14: =U14/U$10 -> #DIV/0! | W14: =SUM(W12:W13) -> 10235891 | Y14: =SUM(Y12:Y13) -> 0 | Z14: =Y14/Y$10 -> #DIV/0! | AA14: =SUM(AA12:AA13) -> 7385414.1 | AC14: =SUM(AC12:AC13) -> 0 | AD14: =AC14/AC$10 -> #DIV/0! | AE14: =SUM(AE12:AE13) -> 11935383 | AG14: =SUM(AG12:AG13) -> 0 | AH14: =AG14/AG$10 -> #DIV/0! | AI14: ='Q1 FY26-27'!AI14 -> 1030 | AJ14: =AI14/AI$10 -> #DIV/0! | AK14: ='Q1 FY26-27'!AK14 -> 0 | AL14: =AK14/AK$10 -> #DIV/0! | AM14: =SUM(AM12:AM13) -> 1900560 | AO14: =SUM(AO12:AO13) -> 0 | AQ14: ='Q1 FY26-27'!AQ14 -> 9521348.3 | AS14: =SUM(AS12:AS13) -> 0 | AU14: =AU12+AU13 -> 447128.12 | AW14: =AW12+AW13 -> 0 | AY14: =AY12+AY13 -> 348625.01 | BA14: =BA12+BA13 -> 0 | BC14: =BC12+BC13 -> 501066.73 | BE14: =BE12+BE13 -> 0 | BG14: =BG12+BG13 -> 442890.24 | BI14: =BI12+BI13 -> 0
B15: DEQ | G15: ='Q1 FY26-27'!G15 -> 0 | I15: ='Q1 FY26-27'!I15 -> 0 | O15: ='Q1 FY26-27'!O15 -> 0 | S15: ='Q1 FY26-27'!S15 -> 0 | U15: ='Q1 FY26-27'!U15 -> 0 | W15: ='Q1 FY26-27'!W15 -> 0 | Y15: ='Q1 FY26-27'!Y15 -> 0 | AA15: ='Q1 FY26-27'!AA15 -> 0 | AE15: ='Q1 FY26-27'!AE15 -> 0 | AG15: ='Q1 FY26-27'!AG15 -> 0 | AI15: ='Q1 FY26-27'!AI15 -> 0 | AK15: ='Q1 FY26-27'!AK15 -> 0 | AM15: ='Q1 FY26-27'!AM15 -> 0 | AO15: ='Q1 FY26-27'!AO15 -> 0 | AQ15: ='Q1 FY26-27'!AQ15 -> 0 | AS15: ='Q1 FY26-27'!AS15 -> 0 | AU15: 0 | AW15: 0 | AY15: 0 | BA15: 0 | BC15: 0 | BE15: 0 | BG15: 0 | BI15: 0
B16: Gross Margin | C16: =C10-C14 -> 91086622 | D16: =C16/C10 -> 0.6120631 | E16: =E10-E14 -> 0 | F16: =E16/E$10 -> #DIV/0! | G16: ='Q1 FY26-27'!G16 -> 0 | H16: =G16/C10 -> 0 | I16: ='Q1 FY26-27'!I16 -> 0 | J16: =I16/E10 -> #DIV/0! | K16: ='Q1 FY26-27'!K16 -> 91086622 | L16: =K16/K10 -> 0.6120631 | M16: =Q16+U16+Y16+AC16+AG16+AK16+AO16 -> 0 | N16: =M16/M$10 -> #DIV/0! | O16: ='Q1 FY26-27'!O16 -> 26567872 | P16: =O16/O$10 -> 0.64903704 | Q16: ='Q1 FY26-27'!Q16 -> 0 | R16: =Q16/Q$10 -> #DIV/0! | S16: ='Q1 FY26-27'!S16 -> 1020620.5 | T16: =S16/S$10 -> 0.61215881 | U16: ='Q1 FY26-27'!U16 -> 0 | V16: =U16/U$10 -> #DIV/0! | W16: ='Q1 FY26-27'!W16 -> 15047185 | X16: =W16/W$10 -> 0.59514851 | Y16: ='Q1 FY26-27'!Y16 -> 0 | Z16: =Y16/Y$10 -> #DIV/0! | AA16: ='Q1 FY26-27'!AA16 -> 11760246 | AB16: =AA16/AA$10 -> 0.61425127 | AC16: ='Q1 FY26-27'!AC16 -> 0 | AD16: =AC16/AC$10 -> #DIV/0! | AE16: ='Q1 FY26-27'!AE16 -> 22297357 | AF16: =AE16/AE$10 -> 0.65134597 | AG16: ='Q1 FY26-27'!AG16 -> 0 | AH16: =AG16/AG$10 -> #DIV/0! | AI16: ='Q1 FY26-27'!AI16 -> -1030 | AJ16: =AI16/AI$10 -> #DIV/0! | AK16: ='Q1 FY26-27'!AK16 -> 0 | AL16: =AK16/AK$10 -> #DIV/0! | AM16: ='Q1 FY26-27'!AM16 -> -929566.16 | AN16: =AM16/AM$10 -> -0.95733479 | AO16: ='Q1 FY26-27'!AO16 -> 0 | AP16: =AO16/AO$10 -> #DIV/0! | AQ16: ='Q1 FY26-27'!AQ16 -> 14624796 | AR16: =AQ16/AQ$10 -> 0.60567832 | AS16: ='Q1 FY26-27'!AS16 -> 0 | AU16: ='Q1 FY26-27'!AU16 -> 219698.87 | AV16: =AU16/AU$10 -> 0.32946907 | AW16: ='Q1 FY26-27'!AW16 -> 0 | AY16: ='Q1 FY26-27'!AY16 -> -120547.12 | BA16: =BA10-BA14 -> 0 | BC16: ='Q1 FY26-27'!BC16 -> -194105.65 | BE16: =BE10-BE14 -> 0 | BG16: ='Q1 FY26-27'!BG16 -> 794094.76 | BI16: =BI10-BI14 -> 0
B17: Average /Month | E17: =E16/12 -> 0 | G17: ='Q1 FY26-27'!G17 -> 0 | I17: ='Q1 FY26-27'!I17 -> 0 | O17: ='Q1 FY26-27'!O17 -> 0 | S17: ='Q1 FY26-27'!S17 -> 0 | U17: ='Q1 FY26-27'!U17 -> 0 | W17: ='Q1 FY26-27'!W17 -> 0 | Y17: ='Q1 FY26-27'!Y17 -> 0 | AA17: ='Q1 FY26-27'!AA17 -> 0 | AE17: ='Q1 FY26-27'!AE17 -> 0 | AG17: ='Q1 FY26-27'!AG17 -> 0 | AI17: ='Q1 FY26-27'!AI17 -> 0 | AK17: ='Q1 FY26-27'!AK17 -> 0 | AM17: ='Q1 FY26-27'!AM17 -> 0 | AO17: ='Q1 FY26-27'!AO17 -> 0 | AQ17: ='Q1 FY26-27'!AQ17 -> 0 | AS17: ='Q1 FY26-27'!AS17 -> 0 | AU17: 0 | AW17: 0 | AY17: 0 | BA17: 0 | BC17: 0 | BE17: 0 | BG17: 0 | BI17: 0
B18: Other Direct Expenses | C18: =G18+K18 -> 3971287.5 | D18: =C18/$C$10 -> 0.026685352 | E18: =I18+M18 -> 0 | F18: =E18/E$10 -> #DIV/0! | G18: ='Q1 FY26-27'!G18 -> 128002.51 | H18: =G18/$C$10 -> 0.00086012208 | I18: ='Q1 FY26-27'!I18 -> 0 | J18: =I18/$C$10 -> 0 | K18: =O18+S18+W18+AA18+AE18+AI18+AM18+AQ18+AU18+AY18+BC18+BG18 -> 3843285 | L18: =K18/$K$10 -> 0.02582523 | M18: =Q18+U18+Y18+AC18+AG18+AK18+AO18 -> 0 | N18: =M18/M$10 -> #DIV/0! | O18: ='Q1 FY26-27'!O18 -> 949580.56 | P18: =O18/O$10 -> 0.023197678 | Q18: ='Q1 FY26-27'!Q18 -> 0 | R18: =Q18/Q$10 -> #DIV/0! | S18: ='Q1 FY26-27'!S18 -> 91280.29 | T18: =S18/S$10 -> 0.054749078 | U18: ='Q1 FY26-27'!U18 -> 0 | V18: =U18/U$10 -> #DIV/0! | W18: ='Q1 FY26-27'!W18 -> 750009.87 | X18: =W18/W$10 -> 0.029664502 | Y18: ='Q1 FY26-27'!Y18 -> 0 | Z18: =Y18/Y$10 -> #DIV/0! | AA18: ='Q1 FY26-27'!AA18 -> 483204.82 | AB18: =AA18/AA$10 -> 0.025238348 | AC18: ='Q1 FY26-27'!AC18 -> 0 | AD18: =AC18/AC$10 -> #DIV/0! | AE18: ='Q1 FY26-27'!AE18 -> 989178.45 | AF18: =AE18/AE$10 -> 0.028895685 | AG18: ='Q1 FY26-27'!AG18 -> 0 | AH18: =AG18/AG$10 -> #DIV/0! | AI18: ='Q1 FY26-27'!AI18 -> 35514 | AJ18: =AI18/AI$10 -> #DIV/0! | AK18: ='Q1 FY26-27'!AK18 -> 0 | AL18: =AK18/AK$10 -> #DIV/0! | AM18: ='Q1 FY26-27'!AM18 -> 71198.86 | AN18: =AM18/AM$10 -> 0.07332576 | AO18: ='Q1 FY26-27'!AO18 -> 0 | AP18: =AO18/AO$10 -> #DIV/0! | AQ18: ='Q1 FY26-27'!AQ18 -> 467605.13 | AR18: =AQ18/AQ$10 -> 0.019365623 | AS18: ='Q1 FY26-27'!AS18 -> 0 | AU18: ='Q1 FY26-27'!AU18 -> 0 | AV18: =AU18/AU$10 -> 0 | AW18: ='Q1 FY26-27'!AW18 -> 0 | AY18: ='Q1 FY26-27'!AY18 -> 0 | BA18: ='Q1 FY26-27'!BA18 -> 0 | BC18: ='Q1 FY26-27'!BC18 -> 0 | BE18: ='Q1 FY26-27'!BE18 -> 0 | BG18: ='Q1 FY26-27'!BG18 -> 5713 | BI18: ='Q1 FY26-27'!BI18 -> 0
B19: Marketing Expenses | C19: =G19+K19 -> 1618158.4 | D19: =C19/$C$10 -> 0.010873332 | E19: =I19+M19 -> 53100 | F19: =E19/E$10 -> #DIV/0! | G19: ='Q1 FY26-27'!G19 -> 106200 | H19: =G19/$C$10 -> 0.00071361853 | I19: ='Q1 FY26-27'!I19 -> 53100 | J19: =I19/$C$10 -> 0.00035680926 | K19: =O19+S19+W19+AA19+AE19+AI19+AM19+AQ19+AU19+AY19+BC19+BG19 -> 1511958.4 | L19: =K19/$K$10 -> 0.010159713 | M19: =Q19+U19+Y19+AC19+AG19+AK19+AO19 -> 0 | N19: =M19/M$10 -> #DIV/0! | O19: ='Q1 FY26-27'!O19 -> 72049 | P19: =O19/O$10 -> 0.0017601135 | Q19: ='Q1 FY26-27'!Q19 -> 0 | R19: =Q19/Q$10 -> #DIV/0! | S19: ='Q1 FY26-27'!S19 -> 179253.69 | T19: =S19/S$10 -> 0.10751471 | U19: ='Q1 FY26-27'!U19 -> 0 | V19: =U19/U$10 -> #DIV/0! | W19: ='Q1 FY26-27'!W19 -> 406787.44 | X19: =W19/W$10 -> 0.016089317 | Y19: ='Q1 FY26-27'!Y19 -> 0 | Z19: =Y19/Y$10 -> #DIV/0! | AA19: ='Q1 FY26-27'!AA19 -> 215071.5 | AB19: =AA19/AA$10 -> 0.011233434 | AC19: ='Q1 FY26-27'!AC19 -> 0 | AD19: =AC19/AC$10 -> #DIV/0! | AE19: ='Q1 FY26-27'!AE19 -> 187484 | AF19: =AE19/AE$10 -> 0.0054767455 | AG19: ='Q1 FY26-27'!AG19 -> 0 | AH19: =AG19/AG$10 -> #DIV/0! | AI19: ='Q1 FY26-27'!AI19 -> 80000 | AJ19: =AI19/AI$10 -> #DIV/0! | AK19: ='Q1 FY26-27'!AK19 -> 0 | AL19: =AK19/AK$10 -> #DIV/0! | AM19: ='Q1 FY26-27'!AM19 -> 103790.78 | AN19: =AM19/AM$10 -> 0.10689129 | AO19: ='Q1 FY26-27'!AO19 -> 0 | AP19: =AO19/AO$10 -> #DIV/0! | AQ19: ='Q1 FY26-27'!AQ19 -> 52063.98 | AR19: =AQ19/AQ$10 -> 0.0021562026 | AS19: ='Q1 FY26-27'!AS19 -> 35000 | AU19: ='Q1 FY26-27'!AU19 -> 113959.52 | AV19: =AU19/AU$10 -> 0.17089818 | AW19: ='Q1 FY26-27'!AW19 -> 0 | AY19: ='Q1 FY26-27'!AY19 -> 43183.46 | BA19: ='Q1 FY26-27'!BA19 -> 0 | BC19: ='Q1 FY26-27'!BC19 -> 43467.03 | BE19: ='Q1 FY26-27'!BE19 -> 0 | BG19: ='Q1 FY26-27'!BG19 -> 14848 | BI19: ='Q1 FY26-27'!BI19 -> 0
B20: Sales Commission | C20: =G20+K20 -> 4609465.1 | D20: =C20/$C$10 -> 0.030973632 | E20: =I20+M20 -> 0 | F20: =E20/E$10 -> #DIV/0! | G20: ='Q1 FY26-27'!G20 -> 0 | H20: =G20/$C$10 -> 0 | I20: ='Q1 FY26-27'!I20 -> 0 | J20: =I20/$C$10 -> 0 | K20: =O20+S20+W20+AA20+AE20+AI20+AM20+AQ20+AU20+AY20+BC20+BG20 -> 4609465.1 | L20: =K20/$K$10 -> 0.030973632 | M20: =Q20+U20+Y20+AC20+AG20+AK20+AO20 -> 0 | N20: =M20/M$10 -> #DIV/0! | O20: ='Q1 FY26-27'!O20 -> 173480.51 | P20: =O20/O$10 -> 0.0042380239 | Q20: ='Q1 FY26-27'!Q20 -> 0 | R20: =Q20/Q$10 -> #DIV/0! | S20: ='Q1 FY26-27'!S20 -> 228974.03 | T20: =S20/S$10 -> 0.13733652 | U20: ='Q1 FY26-27'!U20 -> 0 | V20: =U20/U$10 -> #DIV/0! | W20: ='Q1 FY26-27'!W20 -> 960909.79 | X20: =W20/W$10 -> 0.038006047 | Y20: ='Q1 FY26-27'!Y20 -> 0 | Z20: =Y20/Y$10 -> #DIV/0! | AA20: ='Q1 FY26-27'!AA20 -> 1396555.2 | AB20: =AA20/AA$10 -> 0.072943698 | AC20: ='Q1 FY26-27'!AC20 -> 0 | AD20: =AC20/AC$10 -> #DIV/0! | AE20: ='Q1 FY26-27'!AE20 -> 1307943 | AF20: =AE20/AE$10 -> 0.038207372 | AG20: ='Q1 FY26-27'!AG20 -> 0 | AH20: =AG20/AG$10 -> #DIV/0! | AI20: ='Q1 FY26-27'!AI20 -> 0 | AJ20: =AI20/AI$10 -> #DIV/0! | AK20: ='Q1 FY26-27'!AK20 -> 0 | AL20: =AK20/AK$10 -> #DIV/0! | AM20: ='Q1 FY26-27'!AM20 -> 78387.37 | AN20: =AM20/AM$10 -> 0.08072901 | AO20: ='Q1 FY26-27'!AO20 -> 0 | AP20: =AO20/AO$10 -> #DIV/0! | AQ20: ='Q1 FY26-27'!AQ20 -> 0 | AR20: =AQ20/AQ$10 -> 0 | AS20: ='Q1 FY26-27'!AS20 -> 0 | AU20: ='Q1 FY26-27'!AU20 -> 162351.79 | AV20: =AU20/AU$10 -> 0.24346913 | AW20: ='Q1 FY26-27'!AW20 -> 0 | AY20: ='Q1 FY26-27'!AY20 -> 69035.85 | BA20: ='Q1 FY26-27'!BA20 -> 0 | BC20: ='Q1 FY26-27'!BC20 -> 85672.94 | BE20: ='Q1 FY26-27'!BE20 -> 0 | BG20: ='Q1 FY26-27'!BG20 -> 146154.56 | BI20: ='Q1 FY26-27'!BI20 -> 0
B21: Rental & Utility Expenses | C21: =G21+K21 -> 16374761 | D21: =C21/$C$10 -> 0.11003138 | E21: =I21+M21 -> 3057546 | F21: =E21/E$10 -> #DIV/0! | G21: ='Q1 FY26-27'!G21 -> 1627794.7 | H21: =G21/$C$10 -> 0.010938084 | I21: ='Q1 FY26-27'!I21 -> 0 | J21: =I21/$C$10 -> 0 | K21: =O21+S21+W21+AA21+AE21+AI21+AM21+AQ21+AU21+AY21+BC21+BG21 -> 14746966 | L21: =K21/$K$10 -> 0.099093299 | M21: =Q21+U21+Y21+AC21+AG21+AK21+AO21 -> 3057546 | N21: =M21/M$10 -> #DIV/0! | O21: ='Q1 FY26-27'!O21 -> 3665933.8 | P21: =O21/O$10 -> 0.089556545 | Q21: ='Q1 FY26-27'!Q21 -> 1419717 | R21: =Q21/Q$10 -> #DIV/0! | S21: ='Q1 FY26-27'!S21 -> 213175 | T21: =S21/S$10 -> 0.1278604 | U21: ='Q1 FY26-27'!U21 -> 76212 | V21: =U21/U$10 -> #DIV/0! | W21: ='Q1 FY26-27'!W21 -> 3480038.3 | X21: =W21/W$10 -> 0.13764299 | Y21: ='Q1 FY26-27'!Y21 -> 1314963 | Z21: =Y21/Y$10 -> #DIV/0! | AA21: ='Q1 FY26-27'!AA21 -> 2210248 | AB21: =AA21/AA$10 -> 0.11544382 | AC21: ='Q1 FY26-27'!AC21 -> 0 | AD21: =AC21/AC$10 -> #DIV/0! | AE21: ='Q1 FY26-27'!AE21 -> 2351243 | AF21: =AE21/AE$10 -> 0.068684045 | AG21: ='Q1 FY26-27'!AG21 -> 0 | AH21: =AG21/AG$10 -> #DIV/0! | AI21: ='Q1 FY26-27'!AI21 -> 370741 | AJ21: =AI21/AI$10 -> #DIV/0! | AK21: ='Q1 FY26-27'!AK21 -> 90931 | AL21: =AK21/AK$10 -> #DIV/0! | AM21: ='Q1 FY26-27'!AM21 -> 489829 | AN21: =AM21/AM$10 -> 0.5044615 | AO21: ='Q1 FY26-27'!AO21 -> 155723 | AP21: =AO21/AO$10 -> #DIV/0! | AQ21: ='Q1 FY26-27'!AQ21 -> 1965758 | AR21: =AQ21/AQ$10 -> 0.081410844 | AS21: ='Q1 FY26-27'!AS21 -> 2419 | AU21: ='Q1 FY26-27'!AU21 -> 0 | AV21: =AU21/AU$10 -> 0 | AW21: ='Q1 FY26-27'!AW21 -> 0 | AY21: ='Q1 FY26-27'!AY21 -> 0 | BA21: ='Q1 FY26-27'!BA21 -> 0 | BC21: ='Q1 FY26-27'!BC21 -> 0 | BE21: ='Q1 FY26-27'!BE21 -> 0 | BG21: ='Q1 FY26-27'!BG21 -> 0 | BI21: ='Q1 FY26-27'!BI21 -> 0
B22: Salary & Staff Expenses | C22: =G22+K22 -> 48806327 | D22: =C22/$C$10 -> 0.32795762 | E22: =I22+M22 -> 758150 | F22: =E22/E$10 -> #DIV/0! | G22: ='Q1 FY26-27'!G22 -> 7747821.5 | H22: =G22/$C$10 -> 0.052062043 | I22: ='Q1 FY26-27'!I22 -> 0 | J22: =I22/$C$10 -> 0 | K22: =O22+S22+W22+AA22+AE22+AI22+AM22+AQ22+AU22+AY22+BC22+BG22 -> 41058506 | L22: =K22/$K$10 -> 0.27589558 | M22: =Q22+U22+Y22+AC22+AG22+AK22+AO22 -> 758150 | N22: =M22/M$10 -> #DIV/0! | O22: ='Q1 FY26-27'!O22 -> 10602073 | P22: =O22/O$10 -> 0.25900224 | Q22: ='Q1 FY26-27'!Q22 -> 663750 | R22: =Q22/Q$10 -> #DIV/0! | S22: ='Q1 FY26-27'!S22 -> 679710.73 | T22: =S22/S$10 -> 0.40768424 | U22: ='Q1 FY26-27'!U22 -> 0 | V22: =U22/U$10 -> #DIV/0! | W22: ='Q1 FY26-27'!W22 -> 6422135 | X22: =W22/W$10 -> 0.25400924 | Y22: ='Q1 FY26-27'!Y22 -> 0 | Z22: =Y22/Y$10 -> #DIV/0! | AA22: ='Q1 FY26-27'!AA22 -> 3537149.7 | AB22: =AA22/AA$10 -> 0.18474943 | AC22: ='Q1 FY26-27'!AC22 -> 0 | AD22: =AC22/AC$10 -> #DIV/0! | AE22: ='Q1 FY26-27'!AE22 -> 7545416 | AF22: =AE22/AE$10 -> 0.2204152 | AG22: ='Q1 FY26-27'!AG22 -> 0 | AH22: =AG22/AG$10 -> #DIV/0! | AI22: ='Q1 FY26-27'!AI22 -> 460392 | AJ22: =AI22/AI$10 -> #DIV/0! | AK22: ='Q1 FY26-27'!AK22 -> 0 | AL22: =AK22/AK$10 -> #DIV/0! | AM22: ='Q1 FY26-27'!AM22 -> 3028630.6 | AN22: =AM22/AM$10 -> 3.1191039 | AO22: ='Q1 FY26-27'!AO22 -> 94400 | AP22: =AO22/AO$10 -> #DIV/0! | AQ22: ='Q1 FY26-27'!AQ22 -> 7579231.5 | AR22: =AQ22/AQ$10 -> 0.31388993 | AS22: ='Q1 FY26-27'!AS22 -> 0 | AU22: ='Q1 FY26-27'!AU22 -> 0 | AV22: =AU22/AU$10 -> 0 | AW22: ='Q1 FY26-27'!AW22 -> 0 | AY22: ='Q1 FY26-27'!AY22 -> 0 | BA22: ='Q1 FY26-27'!BA22 -> 0 | BC22: ='Q1 FY26-27'!BC22 -> 0 | BE22: ='Q1 FY26-27'!BE22 -> 0 | BG22: ='Q1 FY26-27'!BG22 -> 1203766.5 | BI22: ='Q1 FY26-27'!BI22 -> 0
B23: Bank and Finance Charges | C23: =G23+K23 -> 2024887 | D23: =C23/$C$10 -> 0.013606373 | E23: =I23+M23 -> 0 | F23: =E23/E$10 -> #DIV/0! | G23: ='Q1 FY26-27'!G23 -> 879987 | H23: =G23/$C$10 -> 0.0059131359 | I23: ='Q1 FY26-27'!I23 -> 0 | J23: =I23/$C$10 -> 0 | K23: =O23+S23+W23+AA23+AE23+AI23+AM23+AQ23+AU23+AY23+BC23+BG23 -> 1144900 | L23: =K23/$K$10 -> 0.0076932376 | M23: =Q23+U23+Y23+AC23+AG23+AK23+AO23 -> 0 | N23: =M23/M$10 -> #DIV/0! | O23: ='Q1 FY26-27'!O23 -> 947509.88 | P23: =O23/O$10 -> 0.023147093 | Q23: ='Q1 FY26-27'!Q23 -> 0 | R23: =Q23/Q$10 -> #DIV/0! | S23: ='Q1 FY26-27'!S23 -> 0 | T23: =S23/S$10 -> 0 | U23: ='Q1 FY26-27'!U23 -> 0 | V23: =U23/U$10 -> #DIV/0! | W23: ='Q1 FY26-27'!W23 -> 46560.5 | X23: =W23/W$10 -> 0.0018415678 | Y23: ='Q1 FY26-27'!Y23 -> 0 | Z23: =Y23/Y$10 -> #DIV/0! | AA23: ='Q1 FY26-27'!AA23 -> 55147.82 | AB23: =AA23/AA$10 -> 0.0028804345 | AC23: ='Q1 FY26-27'!AC23 -> 0 | AD23: =AC23/AC$10 -> #DIV/0! | AE23: ='Q1 FY26-27'!AE23 -> 47677.73 | AF23: =AE23/AE$10 -> 0.0013927524 | AG23: ='Q1 FY26-27'!AG23 -> 0 | AH23: =AG23/AG$10 -> #DIV/0! | AI23: ='Q1 FY26-27'!AI23 -> 0 | AJ23: =AI23/AI$10 -> #DIV/0! | AK23: ='Q1 FY26-27'!AK23 -> 0 | AL23: =AK23/AK$10 -> #DIV/0! | AM23: ='Q1 FY26-27'!AM23 -> 11118.42 | AN23: =AM23/AM$10 -> 0.011450557 | AO23: ='Q1 FY26-27'!AO23 -> 0 | AP23: =AO23/AO$10 -> #DIV/0! | AQ23: ='Q1 FY26-27'!AQ23 -> 36885.62 | AR23: =AQ23/AQ$10 -> 0.0015275987 | AS23: ='Q1 FY26-27'!AS23 -> 0 | AU23: ='Q1 FY26-27'!AU23 -> 0 | AV23: =AU23/AU$10 -> 0 | AW23: ='Q1 FY26-27'!AW23 -> 0 | AY23: ='Q1 FY26-27'!AY23 -> 0 | BA23: ='Q1 FY26-27'!BA23 -> 0 | BC23: ='Q1 FY26-27'!BC23 -> 0 | BE23: ='Q1 FY26-27'!BE23 -> 0 | BG23: ='Q1 FY26-27'!BG23 -> 0 | BI23: ='Q1 FY26-27'!BI23 -> 0
B24: Software and Subscription | C24: =G24+K24 -> 964259.07 | D24: =C24/$C$10 -> 0.0064794081 | E24: =I24+M24 -> 134471.92 | F24: =E24/E$10 -> #DIV/0! | G24: ='Q1 FY26-27'!G24 -> 241237.57 | H24: =G24/$C$10 -> 0.0016210132 | I24: ='Q1 FY26-27'!I24 -> 0 | J24: =I24/$C$10 -> 0 | K24: =O24+S24+W24+AA24+AE24+AI24+AM24+AQ24+AU24+AY24+BC24+BG24 -> 723021.5 | L24: =K24/$K$10 -> 0.0048583949 | M24: =Q24+U24+Y24+AC24+AG24+AK24+AO24 -> 134471.92 | N24: =M24/M$10 -> #DIV/0! | O24: ='Q1 FY26-27'!O24 -> 48494.333 | P24: =O24/O$10 -> 0.0011846872 | Q24: ='Q1 FY26-27'!Q24 -> 0 | R24: =Q24/Q$10 -> #DIV/0! | S24: ='Q1 FY26-27'!S24 -> 46181 | T24: =S24/S$10 -> 0.027698939 | U24: ='Q1 FY26-27'!U24 -> 0 | V24: =U24/U$10 -> #DIV/0! | W24: ='Q1 FY26-27'!W24 -> 127370.67 | X24: =W24/W$10 -> 0.0050377835 | Y24: ='Q1 FY26-27'!Y24 -> 0 | Z24: =Y24/Y$10 -> #DIV/0! | AA24: ='Q1 FY26-27'!AA24 -> 99640.667 | AB24: =AA24/AA$10 -> 0.0052043475 | AC24: ='Q1 FY26-27'!AC24 -> 49820.333 | AD24: =AC24/AC$10 -> #DIV/0! | AE24: ='Q1 FY26-27'!AE24 -> 155690.67 | AF24: =AE24/AE$10 -> 0.0045480049 | AG24: ='Q1 FY26-27'!AG24 -> 77845.333 | AH24: =AG24/AG$10 -> #DIV/0! | AI24: ='Q1 FY26-27'!AI24 -> 13612.5 | AJ24: =AI24/AI$10 -> #DIV/0! | AK24: ='Q1 FY26-27'!AK24 -> 6806.25 | AL24: =AK24/AK$10 -> #DIV/0! | AM24: ='Q1 FY26-27'!AM24 -> 72561.333 | AN24: =AM24/AM$10 -> 0.074728934 | AO24: ='Q1 FY26-27'!AO24 -> 0 | AP24: =AO24/AO$10 -> #DIV/0! | AQ24: ='Q1 FY26-27'!AQ24 -> 6293.3333 | AR24: =AQ24/AQ$10 -> 0.00026063512 | AS24: ='Q1 FY26-27'!AS24 -> 3146.6667 | AU24: ='Q1 FY26-27'!AU24 -> 58819 | AV24: =AU24/AU$10 -> 0.088207287 | AW24: ='Q1 FY26-27'!AW24 -> 0 | AY24: ='Q1 FY26-27'!AY24 -> 46182 | BA24: ='Q1 FY26-27'!BA24 -> 0 | BC24: ='Q1 FY26-27'!BC24 -> 46182 | BE24: ='Q1 FY26-27'!BE24 -> 0 | BG24: ='Q1 FY26-27'!BG24 -> 1994 | BI24: ='Q1 FY26-27'!BI24 -> 0
B25: Other Outlet Costs | C25: =G25+K25 -> 10055140 | D25: =C25/$C$10 -> 0.067566236 | E25: =I25+M25 -> 356555.58 | F25: =E25/E$10 -> #DIV/0! | G25: ='Q1 FY26-27'!G25 -> 2356900 | H25: =G25/$C$10 -> 0.015837359 | I25: ='Q1 FY26-27'!I25 -> 737.5 | J25: =I25/$C$10 -> 4.9556842e-06 | K25: =O25+S25+W25+AA25+AE25+AI25+AM25+AQ25+AU25+AY25+BC25+BG25 -> 7698240.1 | L25: =K25/$K$10 -> 0.051728877 | M25: =Q25+U25+Y25+AC25+AG25+AK25+AO25 -> 355818.08 | N25: =M25/M$10 -> #DIV/0! | O25: ='Q1 FY26-27'!O25 -> 2374341.3 | P25: =O25/O$10 -> 0.05800372 | Q25: ='Q1 FY26-27'!Q25 -> 184154.58 | R25: =Q25/Q$10 -> #DIV/0! | S25: ='Q1 FY26-27'!S25 -> 155919 | T25: =S25/S$10 -> 0.093518781 | U25: ='Q1 FY26-27'!U25 -> 0 | V25: =U25/U$10 -> #DIV/0! | W25: ='Q1 FY26-27'!W25 -> 1114412.7 | X25: =W25/W$10 -> 0.044077415 | Y25: ='Q1 FY26-27'!Y25 -> 0 | Z25: =Y25/Y$10 -> #DIV/0! | AA25: ='Q1 FY26-27'!AA25 -> 468887.5 | AB25: =AA25/AA$10 -> 0.024490537 | AC25: ='Q1 FY26-27'!AC25 -> 15522.25 | AD25: =AC25/AC$10 -> #DIV/0! | AE25: ='Q1 FY26-27'!AE25 -> 922235.09 | AF25: =AE25/AE$10 -> 0.026940149 | AG25: ='Q1 FY26-27'!AG25 -> 133043 | AH25: =AG25/AG$10 -> #DIV/0! | AI25: ='Q1 FY26-27'!AI25 -> 1414742.5 | AJ25: =AI25/AI$10 -> #DIV/0! | AK25: ='Q1 FY26-27'!AK25 -> 5934.9167 | AL25: =AK25/AK$10 -> #DIV/0! | AM25: ='Q1 FY26-27'!AM25 -> 161457.6 | AN25: =AM25/AM$10 -> 0.16628077 | AO25: ='Q1 FY26-27'!AO25 -> 17163.333 | AP25: =AO25/AO$10 -> #DIV/0! | AQ25: ='Q1 FY26-27'!AQ25 -> 994208.45 | AR25: =AQ25/AQ$10 -> 0.041174625 | AS25: ='Q1 FY26-27'!AS25 -> 212632.08 | AU25: ='Q1 FY26-27'!AU25 -> 8100 | AV25: =AU25/AU$10 -> 0.012147079 | AW25: ='Q1 FY26-27'!AW25 -> 0 | AY25: ='Q1 FY26-27'!AY25 -> 8100 | BA25: ='Q1 FY26-27'!BA25 -> 0 | BC25: ='Q1 FY26-27'!BC25 -> 0 | BE25: ='Q1 FY26-27'!BE25 -> 0 | BG25: ='Q1 FY26-27'!BG25 -> 75836 | BI25: ='Q1 FY26-27'!BI25 -> 0
B26: Other Professional Fees | C26: =G26+K26 -> 925817 | D26: =C26/$C$10 -> 0.0062210938 | E26: =I26+M26 -> 10010 | F26: =E26/E$10 -> #DIV/0! | G26: ='Q1 FY26-27'!G26 -> 828298 | H26: =G26/$C$10 -> 0.0055658079 | I26: ='Q1 FY26-27'!I26 -> 0 | J26: =I26/$C$10 -> 0 | K26: =O26+S26+W26+AA26+AE26+AI26+AM26+AQ26+AU26+AY26+BC26+BG26 -> 97519 | L26: =K26/$K$10 -> 0.00065528593 | M26: =Q26+U26+Y26+AC26+AG26+AK26+AO26 -> 10010 | N26: =M26/M$10 -> #DIV/0! | O26: ='Q1 FY26-27'!O26 -> 40644 | P26: =O26/O$10 -> 0.00099290832 | Q26: ='Q1 FY26-27'!Q26 -> 0 | R26: =Q26/Q$10 -> #DIV/0! | S26: ='Q1 FY26-27'!S26 -> 0 | T26: =S26/S$10 -> 0 | U26: ='Q1 FY26-27'!U26 -> 0 | V26: =U26/U$10 -> #DIV/0! | W26: ='Q1 FY26-27'!W26 -> 20335 | X26: =W26/W$10 -> 0.00080429294 | Y26: ='Q1 FY26-27'!Y26 -> 0 | Z26: =Y26/Y$10 -> #DIV/0! | AA26: ='Q1 FY26-27'!AA26 -> 0 | AB26: =AA26/AA$10 -> 0 | AC26: ='Q1 FY26-27'!AC26 -> 0 | AD26: =AC26/AC$10 -> #DIV/0! | AE26: ='Q1 FY26-27'!AE26 -> 20020 | AF26: =AE26/AE$10 -> 0.00058482028 | AG26: ='Q1 FY26-27'!AG26 -> 10010 | AH26: =AG26/AG$10 -> #DIV/0! | AI26: ='Q1 FY26-27'!AI26 -> 0 | AJ26: =AI26/AI$10 -> #DIV/0! | AK26: ='Q1 FY26-27'!AK26 -> 0 | AL26: =AK26/AK$10 -> #DIV/0! | AM26: ='Q1 FY26-27'!AM26 -> 0 | AN26: =AM26/AM$10 -> 0 | AO26: ='Q1 FY26-27'!AO26 -> 0 | AP26: =AO26/AO$10 -> #DIV/0! | AQ26: ='Q1 FY26-27'!AQ26 -> 16520 | AR26: =AQ26/AQ$10 -> 0.0006841672 | AS26: ='Q1 FY26-27'!AS26 -> 8260 | AU26: ='Q1 FY26-27'!AU26 -> 0 | AV26: =AU26/AU$10 -> 0 | AW26: ='Q1 FY26-27'!AW26 -> 0 | AY26: ='Q1 FY26-27'!AY26 -> 0 | BA26: ='Q1 FY26-27'!BA26 -> 0 | BC26: ='Q1 FY26-27'!BC26 -> 0 | BE26: ='Q1 FY26-27'!BE26 -> 0 | BG26: ='Q1 FY26-27'!BG26 -> 0 | BI26: ='Q1 FY26-27'!BI26 -> 0
B27: Other Expenses | C27: =G27+K27 -> -3653883.6 | D27: =C27/$C$10 -> -0.024552533 | E27: =I27+M27 -> 0 | F27: =E27/E$10 -> #DIV/0! | G27: ='Q1 FY26-27'!G27 -> 352790.41 | H27: =G27/$C$10 -> 0.0023706005 | I27: ='Q1 FY26-27'!I27 -> 0 | J27: =I27/$C$10 -> 0 | K27: =O27+S27+W27+AA27+AE27+AI27+AM27+AQ27+AU27+AY27+BC27+BG27 -> -4006674 | L27: =K27/$K$10 -> -0.026923134 | M27: =Q27+U27+Y27+AC27+AG27+AK27+AO27 -> 0 | N27: =M27/M$10 -> #DIV/0! | O27: ='Q1 FY26-27'!O27 -> 0 | P27: =O27/O$10 -> 0 | Q27: ='Q1 FY26-27'!Q27 -> 0 | R27: =Q27/Q$10 -> #DIV/0! | S27: ='Q1 FY26-27'!S27 -> 0 | T27: =S27/S$10 -> 0 | U27: ='Q1 FY26-27'!U27 -> 0 | V27: =U27/U$10 -> #DIV/0! | W27: ='Q1 FY26-27'!W27 -> 0 | X27: =W27/W$10 -> 0 | Y27: ='Q1 FY26-27'!Y27 -> 0 | Z27: =Y27/Y$10 -> #DIV/0! | AA27: ='Q1 FY26-27'!AA27 -> 0 | AB27: =AA27/AA$10 -> 0 | AC27: ='Q1 FY26-27'!AC27 -> 0 | AD27: =AC27/AC$10 -> #DIV/0! | AE27: ='Q1 FY26-27'!AE27 -> 0 | AF27: =AE27/AE$10 -> 0 | AG27: ='Q1 FY26-27'!AG27 -> 0 | AH27: =AG27/AG$10 -> #DIV/0! | AI27: ='Q1 FY26-27'!AI27 -> 0 | AJ27: =AI27/AI$10 -> #DIV/0! | AK27: ='Q1 FY26-27'!AK27 -> 0 | AL27: =AK27/AK$10 -> #DIV/0! | AM27: ='Q1 FY26-27'!AM27 -> -4016974 | AN27: =AM27/AM$10 -> -4.1369717 | AO27: ='Q1 FY26-27'!AO27 -> 0 | AP27: =AO27/AO$10 -> #DIV/0! | AQ27: ='Q1 FY26-27'!AQ27 -> 0 | AR27: =AQ27/AQ$10 -> 0 | AS27: ='Q1 FY26-27'!AS27 -> 0 | AU27: ='Q1 FY26-27'!AU27 -> 0 | AV27: =AU27/AU$10 -> 0 | AW27: ='Q1 FY26-27'!AW27 -> 0 | AY27: ='Q1 FY26-27'!AY27 -> 0 | BA27: ='Q1 FY26-27'!BA27 -> 0 | BC27: ='Q1 FY26-27'!BC27 -> 0 | BE27: ='Q1 FY26-27'!BE27 -> 0 | BG27: ='Q1 FY26-27'!BG27 -> 10300 | BI27: ='Q1 FY26-27'!BI27 -> 0
B28: Total Other Expenses | C28: =SUM(C18:C27) -> 85696219 | D28: =C28/C10 -> 0.5758419 | E28: =I28+M28 -> 4369833.5 | F28: =E28/E$10 -> #DIV/0! | G28: ='Q1 FY26-27'!G28 -> 14269032 | H28: =G28/C10 -> 0.095881784 | I28: ='Q1 FY26-27'!I28 -> 53837.5 | J28: =I28/E10 -> #DIV/0! | K28: =SUM(K18:K27) -> 71427187 | L28: =K28/$K$10 -> 0.47996011 | M28: =SUM(M18:M27) -> 4315996 | N28: =M28/M$10 -> #DIV/0! | O28: =SUM(O18:O27) -> 18874107 | P28: =O28/O$10 -> 0.46108301 | Q28: =SUM(Q18:Q27) -> 2267621.6 | R28: =Q28/Q$10 -> #DIV/0! | S28: =SUM(S18:S27) -> 1594493.7 | T28: =S28/S$10 -> 0.95636266 | U28: ='Q1 FY26-27'!U28 -> 76212 | V28: =U28/U$10 -> #DIV/0! | W28: =SUM(W18:W27) -> 13328559 | X28: =W28/W$10 -> 0.52717316 | Y28: ='Q1 FY26-27'!Y28 -> 1314963 | Z28: =Y28/Y$10 -> #DIV/0! | AA28: =SUM(AA18:AA27) -> 8465905.3 | AB28: =AA28/AA$10 -> 0.44218404 | AC28: ='Q1 FY26-27'!AC28 -> 65342.583 | AD28: =AC28/AC$10 -> #DIV/0! | AE28: =SUM(AE18:AE27) -> 13526888 | AF28: =AE28/AE$10 -> 0.39514477 | AG28: ='Q1 FY26-27'!AG28 -> 220898.33 | AH28: =AG28/AG$10 -> #DIV/0! | AI28: =SUM(AI18:AI27) -> 2375002 | AJ28: =AI28/AI$10 -> #DIV/0! | AK28: ='Q1 FY26-27'!AK28 -> 103672.17 | AL28: =AK28/AK$10 -> #DIV/0! | AM28: =SUM(AM18:AM27) -> -0.06 | AN28: =AM28/AM$10 -> -6.179236e-08 | AO28: ='Q1 FY26-27'!AO28 -> 267286.33 | AP28: =AO28/AO$10 -> #DIV/0! | AQ28: =SUM(AQ18:AQ27) -> 11118566 | AR28: =AQ28/AQ$10 -> 0.46046962 | AS28: ='Q1 FY26-27'!AS28 -> 261457.75 | AU28: =SUM(AU18:AU27) -> 343230.31 | AV28: =AU28/AU$10 -> 0.51472168 | AW28: =SUM(AW18:AW27) -> 0 | AY28: =SUM(AY18:AY27) -> 166501.31 | BA28: =SUM(BA18:BA27) -> 0 | BC28: =SUM(BC18:BC27) -> 175321.97 | BE28: =SUM(BE18:BE27) -> 0 | BG28: =SUM(BG18:BG27) -> 1458612.1 | BI28: =SUM(BI18:BI27) -> 0
B30: EBIDTA | C30: =C16-C28 -> 5390403.2 | D30: =C30/C$10 -> 0.036221201 | E30: =E16-E28 -> -4369833.5 | F30: =E30/E$10 -> #DIV/0! | G30: =G16-G28 -> -14269032 | H30: =G30/C10 -> -0.095881784 | I30: =I16-I28 -> -53837.5 | J30: =I30/E10 -> #DIV/0! | K30: =K16-K28 -> 19659435 | L30: =K30/$K$10 -> 0.13210299 | M30: =M16-M28 -> -4315996 | N30: =M30/M$10 -> #DIV/0! | O30: =O16-O28 -> 7693765.5 | P30: =O30/O$10 -> 0.18795404 | Q30: =Q16-Q28 -> -2267621.6 | R30: =Q30/Q$10 -> #DIV/0! | S30: =S16-S28 -> -573873.19 | T30: =S30/S$10 -> -0.34420386 | U30: =U16-U28 -> -76212 | V30: =U30/U$10 -> #DIV/0! | W30: =W16-W28 -> 1718626.1 | X30: =W30/W$10 -> 0.067975355 | Y30: =Y16-Y28 -> -1314963 | Z30: =Y30/Y$10 -> #DIV/0! | AA30: =AA16-AA28 -> 3294340.5 | AB30: =AA30/AA$10 -> 0.17206722 | AC30: =AC16-AC28 -> -65342.583 | AD30: =AC30/AC$10 -> #DIV/0! | AE30: =AE16-AE28 -> 8770468.7 | AF30: =AE30/AE$10 -> 0.2562012 | AG30: =AG16-AG28 -> -220898.33 | AH30: =AG30/AG$10 -> #DIV/0! | AI30: =AI16-AI28 -> -2376032 | AJ30: =AI30/AI$10 -> #DIV/0! | AK30: =AK16-AK28 -> -103672.17 | AL30: =AK30/AK$10 -> #DIV/0! | AM30: =AM16-AM28 -> -929566.1 | AN30: =AM30/AM$10 -> -0.95733473 | AO30: =AO16-AO28 -> -267286.33 | AP30: =AO30/AO$10 -> #DIV/0! | AQ30: =AQ16-AQ28 -> 3506230.1 | AR30: =AQ30/AQ$10 -> 0.1452087 | AS30: =AS16-AS28 -> -261457.75 | AT30: =AS30/AS$10 -> #DIV/0! | AU30: =AU16-AU28 -> -123531.44 | AV30: =AU30/AU$10 -> -0.18525261 | AW30: =AW16-AW28 -> 0 | AY30: =AY16-AY28 -> -287048.43 | BA30: =BA16-BA28 -> 0 | BC30: =BC16-BC28 -> -369427.62 | BE30: =BE16-BE28 -> 0 | BG30: =BG16-BG28 -> -664517.3 | BI30: =BI16-BI28 -> 0
C33: ='Q1 FY26-27'!C10 -> 1.4881901e+08 | G33: ='Q1 FY26-27'!G10 -> 0 | K33: ='Q1 FY26-27'!K10 -> 1.4881901e+08 | O33: ='Q1 FY26-27'!O10 -> 40934293 | S33: ='Q1 FY26-27'!S10 -> 1667248 | W33: ='Q1 FY26-27'!W10 -> 25283076 | AA33: ='Q1 FY26-27'!AA10 -> 19145660 | AE33: ='Q1 FY26-27'!AE10 -> 34232739 | AI33: ='Q1 FY26-27'!AI10 -> 0 | AM33: ='Q1 FY26-27'!AM10 -> 970993.82 | AQ33: ='Q1 FY26-27'!AQ10 -> 24146144 | AU33: ='Q1 FY26-27'!AU10 -> 666826.99 | AY33: ='Q1 FY26-27'!AY10 -> 228077.89 | BC33: ='Q1 FY26-27'!BC10 -> 306961.08 | BG33: ='Q1 FY26-27'!BG10 -> 1236985
C35: =C10-C33 -> 0 | G35: =G10-G33 -> 0 | K35: =K10-K33 -> 0 | O35: =O10-O33 -> 0 | S35: =S10-S33 -> 0 | W35: =W10-W33 -> 0 | AA35: =AA10-AA33 -> 0 | AE35: =AE10-AE33 -> 0 | AI35: =AI10-AI33 -> 0 | AM35: =AM10-AM33 -> 0 | AQ35: =AQ10-AQ33 -> 0 | AU35: =AU10-AU33 -> 0 | AY35: =AY10-AY33 -> 0 | BC35: =BC10-BC33 -> 0 | BG35: =BG10-BG33 -> 0

Sheet Q1 FY26-27
B1: FY26-27 Budgeted vs Actual MIS
B2: Food Matters Group | Quarter 1 | FY26-27
B3: Particulars | C3: Total with HO | G3: HO | K3: Outlets Total | O3: Table Total | S3: Iktara | W3: Mg St Colaba | AA3: Mg St LP | AE3: Mg St Bandra | AI3: MSK Events | AM3: MSBC | AQ3: Kaspers | AU3: MSBC Andheri | AY3: MSBC Dahisar | BC3: MSBC Juhu/Goregaon | BG3: Loud Mouth
C4: Amount | D4: %age | E4: Budgeted | F4: %age | G4: Amount | H4: %age | I4: Budgeted | J4: %age | K4: Amount | L4: %age | M4: Budgeted | N4: %age | O4: Amount | P4: %age | Q4: Budgeted | R4: %age | S4: Amount | T4: %age | U4: Budgeted | V4: %age | W4: Amount | X4: %age | Y4: Budgeted | Z4: %age | AA4: Amount | AB4: %age | AC4: Budgeted | AD4: %age | AE4: Amount | AF4: %age | AG4: Budgeted | AH4: %age | AI4: Amount | AJ4: %age | AK4: Budgeted | AL4: %age | AM4: Amount | AN4: %age | AO4: Budgeted | AP4: %age | AQ4: Amount | AR4: %age | AS4: Budgeted | AT4: %age | AU4: Amount | AV4: %age | AW4: Budgeted | AX4: %age | AY4: Amount | AZ4: %age | BA4: Budgeted | BB4: %age | BC4: Amount | BD4: %age | BE4: Budgeted | BF4: %age | BG4: Amount | BH4: %age | BI4: Budgeted | BJ4: %age
B5: Beverage | C5: =G5+K5 -> 11608400 | D5: =C5/$C$10 -> 0.078003476 | E5: =I5+M5 -> 0 | F5: =E5/$E$10 -> #DIV/0! | G5: ='Summary Sheet - April 2026'!G5 + 'Summary Sheet - May 2026'!G5 -> 0 | I5: ='Summary Sheet - April 2026'!I5 -> 0 | K5: =O5+S5+W5+AA5+AE5+AI5+AM5+AQ5+AU5+AY5+BC5+BG5 -> 11608400 | M5: =Q5+U5+Y5+AC5+AG5+AK5+AO5 -> 0 | O5: ='Summary Sheet - April 2026'!O5 + 'Summary Sheet - May 2026'!O5 -> 2407580 | Q5: ='Summary Sheet - April 2026'!Q5 -> 0 | S5: ='Summary Sheet - April 2026'!S5 + 'Summary Sheet - May 2026'!S5 -> 0 | U5: ='Summary Sheet - April 2026'!U5 -> 0 | W5: ='Summary Sheet - April 2026'!W5+'Summary Sheet - May 2026'!W5 -> 2398144 | Y5: ='Summary Sheet - April 2026'!Y5 -> 0 | AA5: ='Summary Sheet - April 2026'!AA5 + 'Summary Sheet - May 2026'!AA5 -> 2390099.8 | AC5: ='Summary Sheet - April 2026'!AC5 -> 0 | AE5: ='Summary Sheet - April 2026'!AE5 + 'Summary Sheet - May 2026'!AE5 -> 3237788.5 | AG5: ='Summary Sheet - April 2026'!AG5 -> 0 | AI5: ='Summary Sheet - April 2026'!AI5 + 'Summary Sheet - May 2026'!AI5 -> 0 | AK5: ='Summary Sheet - April 2026'!AK5 -> 0 | AM5: ='Summary Sheet - April 2026'!AM5 + 'Summary Sheet - May 2026'!AM5 -> 0 | AO5: ='Summary Sheet - April 2026'!AO5 -> 0 | AQ5: ='Summary Sheet - April 2026'!AQ5 + 'Summary Sheet - May 2026'!AQ5 -> 1174787.5 | AS5: ='Summary Sheet - April 2026'!AS5 -> 0 | AU5: ='Summary Sheet - April 2026'!AU5 + 'Summary Sheet - May 2026'!AU5 -> 0 | AW5: ='Summary Sheet - April 2026'!AW5 -> 0 | AY5: ='Summary Sheet - April 2026'!AY5 + 'Summary Sheet - May 2026'!AY5 -> 0 | BA5: ='Summary Sheet - April 2026'!BL5 -> 0 | BC5: ='Summary Sheet - April 2026'!BC5 + 'Summary Sheet - May 2026'!BC5 -> 0 | BE5: ='Summary Sheet - April 2026'!BP5 -> 0 | BG5: ='Summary Sheet - April 2026'!BG5 + 'Summary Sheet - May 2026'!BG5 -> 0 | BI5: ='Summary Sheet - April 2026'!BT5 -> 0
B6: Liquor | C6: =G6+K6 -> 24020516 | D6: =C6/$C$10 -> 0.16140758 | E6: =I6+M6 -> 0 | F6: =E6/$E$10 -> #DIV/0! | G6: ='Summary Sheet - April 2026'!G6 + 'Summary Sheet - May 2026'!G6 -> 0 | I6: ='Summary Sheet - April 2026'!I6 -> 0 | K6: =O6+S6+W6+AA6+AE6+AI6+AM6+AQ6+AU6+AY6+BC6+BG6 -> 24020516 | M6: =Q6+U6+Y6+AC6+AG6+AK6+AO6 -> 0 | O6: ='Summary Sheet - April 2026'!O6 + 'Summary Sheet - May 2026'!O6 -> 9818016 | Q6: ='Summary Sheet - April 2026'!Q6 -> 0 | S6: ='Summary Sheet - April 2026'!S6 + 'Summary Sheet - May 2026'!S6 -> 0 | U6: ='Summary Sheet - April 2026'!U6 -> 0 | W6: ='Summary Sheet - April 2026'!W6+'Summary Sheet - May 2026'!W6 -> 1505040 | Y6: ='Summary Sheet - April 2026'!Y6 -> 0 | AA6: ='Summary Sheet - April 2026'!AA6 + 'Summary Sheet - May 2026'!AA6 -> 0 | AC6: ='Summary Sheet - April 2026'!AC6 -> 0 | AE6: ='Summary Sheet - April 2026'!AE6 + 'Summary Sheet - May 2026'!AE6 -> 4194442.5 | AG6: ='Summary Sheet - April 2026'!AG6 -> 0 | AI6: ='Summary Sheet - April 2026'!AI6 + 'Summary Sheet - May 2026'!AI6 -> 0 | AK6: ='Summary Sheet - April 2026'!AK6 -> 0 | AM6: ='Summary Sheet - April 2026'!AM6 + 'Summary Sheet - May 2026'!AM6 -> 0 | AO6: ='Summary Sheet - April 2026'!AO6 -> 0 | AQ6: ='Summary Sheet - April 2026'!AQ6 + 'Summary Sheet - May 2026'!AQ6 -> 8503017.5 | AS6: ='Summary Sheet - April 2026'!AS6 -> 0 | AU6: ='Summary Sheet - April 2026'!AU6 + 'Summary Sheet - May 2026'!AU6 -> 0 | AW6: ='Summary Sheet - April 2026'!AW6 -> 0 | AY6: ='Summary Sheet - April 2026'!AY6 + 'Summary Sheet - May 2026'!AY6 -> 0 | BA6: ='Summary Sheet - April 2026'!BL6 -> 0 | BC6: ='Summary Sheet - April 2026'!BC6 + 'Summary Sheet - May 2026'!BC6 -> 0 | BE6: ='Summary Sheet - April 2026'!BP6 -> 0 | BG6: ='Summary Sheet - April 2026'!BG6 + 'Summary Sheet - May 2026'!BG6 -> 0 | BI6: ='Summary Sheet - April 2026'!BT6 -> 0
B7: Food | C7: =G7+K7 -> 1.0826025e+08 | D7: =C7/$C$10 -> 0.72746255 | E7: =I7+M7 -> 0 | F7: =E7/$E$10 -> #DIV/0! | G7: ='Summary Sheet - April 2026'!G7 + 'Summary Sheet - May 2026'!G7 -> 0 | I7: ='Summary Sheet - April 2026'!I7 -> 0 | K7: =O7+S7+W7+AA7+AE7+AI7+AM7+AQ7+AU7+AY7+BC7+BG7 -> 1.0826025e+08 | M7: =Q7+U7+Y7+AC7+AG7+AK7+AO7 -> 0 | O7: ='Summary Sheet - April 2026'!O7 + 'Summary Sheet - May 2026'!O7 -> 26989559 | Q7: ='Summary Sheet - April 2026'!Q7 -> 0 | S7: ='Summary Sheet - April 2026'!S7 + 'Summary Sheet - May 2026'!S7 -> 1667248 | U7: ='Summary Sheet - April 2026'!U7 -> 0 | W7: ='Summary Sheet - April 2026'!W7+'Summary Sheet - May 2026'!W7 -> 20658266 | Y7: ='Summary Sheet - April 2026'!Y7 -> 0 | AA7: ='Summary Sheet - April 2026'!AA7 + 'Summary Sheet - May 2026'!AA7 -> 16390588 | AC7: ='Summary Sheet - April 2026'!AC7 -> 0 | AE7: ='Summary Sheet - April 2026'!AE7 + 'Summary Sheet - May 2026'!AE7 -> 25758068 | AG7: ='Summary Sheet - April 2026'!AG7 -> 0 | AI7: ='Summary Sheet - April 2026'!AI7 + 'Summary Sheet - May 2026'!AI7 -> 0 | AK7: ='Summary Sheet - April 2026'!AK7 -> 0 | AM7: ='Summary Sheet - April 2026'!AM7 + 'Summary Sheet - May 2026'!AM7 -> 970993.82 | AO7: ='Summary Sheet - April 2026'!AO7 -> 0 | AQ7: ='Summary Sheet - April 2026'!AQ7 + 'Summary Sheet - May 2026'!AQ7 -> 13386680 | AS7: ='Summary Sheet - April 2026'!AS7 -> 0 | AU7: ='Summary Sheet - April 2026'!AU7 + 'Summary Sheet - May 2026'!AU7 -> 666826.99 | AW7: ='Summary Sheet - April 2026'!AW7 -> 0 | AY7: ='Summary Sheet - April 2026'!AY7 + 'Summary Sheet - May 2026'!AY7 -> 228077.89 | BA7: ='Summary Sheet - April 2026'!BL7 -> 0 | BC7: ='Summary Sheet - April 2026'!BC7 + 'Summary Sheet - May 2026'!BC7 -> 306961.08 | BE7: ='Summary Sheet - April 2026'!BP7 -> 0 | BG7: ='Summary Sheet - April 2026'!BG7 + 'Summary Sheet - May 2026'!BG7 -> 1236985 | BI7: ='Summary Sheet - April 2026'!BT7 -> 0
B8: Service Charge | C8: =G8+K8 -> 4894605 | D8: =C8/$C$10 -> 0.03288965 | E8: =I8+M8 -> 0 | F8: =E8/$E$10 -> #DIV/0! | G8: ='Summary Sheet - April 2026'!G8 + 'Summary Sheet - May 2026'!G8 -> 0 | I8: ='Summary Sheet - April 2026'!I8 -> 0 | K8: =O8+S8+W8+AA8+AE8+AI8+AM8+AQ8+AU8+AY8+BC8+BG8 -> 4894605 | M8: =Q8+U8+Y8+AC8+AG8+AK8+AO8 -> 0 | O8: ='Summary Sheet - April 2026'!O8 + 'Summary Sheet - May 2026'!O8 -> 1719138 | Q8: ='Summary Sheet - April 2026'!Q8 -> 0 | S8: ='Summary Sheet - April 2026'!S8 + 'Summary Sheet - May 2026'!S8 -> 0 | U8: ='Summary Sheet - April 2026'!U8 -> 0 | W8: ='Summary Sheet - April 2026'!W8+'Summary Sheet - May 2026'!W8 -> 721626 | Y8: ='Summary Sheet - April 2026'!Y8 -> 0 | AA8: ='Summary Sheet - April 2026'!AA8 + 'Summary Sheet - May 2026'!AA8 -> 356972.05 | AC8: ='Summary Sheet - April 2026'!AC8 -> 0 | AE8: ='Summary Sheet - April 2026'!AE8 + 'Summary Sheet - May 2026'!AE8 -> 1028709 | AG8: ='Summary Sheet - April 2026'!AG8 -> 0 | AI8: ='Summary Sheet - April 2026'!AI8 + 'Summary Sheet - May 2026'!AI8 -> 0 | AK8: ='Summary Sheet - April 2026'!AK8 -> 0 | AM8: ='Summary Sheet - April 2026'!AM8 + 'Summary Sheet - May 2026'!AM8 -> 0 | AO8: ='Summary Sheet - April 2026'!AO8 -> 0 | AQ8: ='Summary Sheet - April 2026'!AQ8 + 'Summary Sheet - May 2026'!AQ8 -> 1068160 | AS8: ='Summary Sheet - April 2026'!AS8 -> 0 | AU8: ='Summary Sheet - April 2026'!AU8 + 'Summary Sheet - May 2026'!AU8 -> 0 | AW8: ='Summary Sheet - April 2026'!AW8 -> 0 | AY8: ='Summary Sheet - April 2026'!AY8 + 'Summary Sheet - May 2026'!AY8 -> 0 | BA8: ='Summary Sheet - April 2026'!BL8 -> 0 | BC8: ='Summary Sheet - April 2026'!BC8 + 'Summary Sheet - May 2026'!BC8 -> 0 | BE8: ='Summary Sheet - April 2026'!BP8 -> 0 | BG8: ='Summary Sheet - April 2026'!BG8 + 'Summary Sheet - May 2026'!BG8 -> 0 | BI8: ='Summary Sheet - April 2026'!BT8 -> 0
B9: Scrap Sales | C9: =G9+K9 -> 35231 | D9: =C9/$C$10 -> 0.00023673724 | E9: =I9+M9 -> 0 | F9: =E9/$E$10 -> #DIV/0! | K9: =O9+S9+W9+AA9+AE9+AI9+AM9+AQ9+AU9+AY9+BC9+BG9 -> 35231 | M9: =Q9+U9+Y9+AC9+AG9+AK9+AO9 -> 0 | O9: ='Summary Sheet - April 2026'!O9 + 'Summary Sheet - May 2026'!O9 -> 0 | Q9: ='Summary Sheet - April 2026'!Q9 -> 0 | S9: ='Summary Sheet - April 2026'!S9 + 'Summary Sheet - May 2026'!S9 -> 0 | U9: ='Summary Sheet - April 2026'!U9 -> 0 | W9: ='Summary Sheet - April 2026'!W9+'Summary Sheet - May 2026'!W9 -> 0 | Y9: ='Summary Sheet - April 2026'!Y9 -> 0 | AA9: ='Summary Sheet - April 2026'!AA9 + 'Summary Sheet - May 2026'!AA9 -> 8000 | AC9: ='Summary Sheet - April 2026'!AC9 -> 0 | AE9: ='Summary Sheet - April 2026'!AE9 + 'Summary Sheet - May 2026'!AE9 -> 13731 | AG9: ='Summary Sheet - April 2026'!AG9 -> 0 | AI9: ='Summary Sheet - April 2026'!AI9 + 'Summary Sheet - May 2026'!AI9 -> 0 | AK9: ='Summary Sheet - April 2026'!AK9 -> 0 | AM9: ='Summary Sheet - April 2026'!AM9 + 'Summary Sheet - May 2026'!AM9 -> 0 | AO9: ='Summary Sheet - April 2026'!AO9 -> 0 | AQ9: ='Summary Sheet - April 2026'!AQ9 + 'Summary Sheet - May 2026'!AQ9 -> 13500 | AS9: ='Summary Sheet - April 2026'!AS9 -> 0 | AU9: ='Summary Sheet - April 2026'!AU9 + 'Summary Sheet - May 2026'!AU9 -> 0 | AW9: ='Summary Sheet - April 2026'!AW9 -> 0 | AY9: ='Summary Sheet - April 2026'!AY9 + 'Summary Sheet - May 2026'!AY9 -> 0 | BA9: ='Summary Sheet - April 2026'!BL9 -> 0 | BC9: ='Summary Sheet - April 2026'!BC9 + 'Summary Sheet - May 2026'!BC9 -> 0 | BE9: ='Summary Sheet - April 2026'!BP9 -> 0 | BG9: ='Summary Sheet - April 2026'!BG9 + 'Summary Sheet - May 2026'!BG9 -> 0 | BI9: ='Summary Sheet - April 2026'!BT9 -> 0
B10: Total Sales Revenue | C10: =SUM(C5:C9) -> 1.4881901e+08 | D10: =C10/C10 -> 1 | E10: =SUM(E5:E9) -> 0 | F10: =E10/E10 -> #DIV/0! | G10: =SUM(G5:G8) -> 0 | I10: =SUM(I5:I8) -> 0 | K10: =SUM(K5:K9) -> 1.4881901e+08 | M10: =SUM(M5:M9) -> 0 | O10: ='Summary Sheet - April 2026'!O10 + 'Summary Sheet - May 2026'!O10 -> 40934293 | Q10: ='Summary Sheet - April 2026'!Q10 -> 0 | S10: ='Summary Sheet - April 2026'!S10 + 'Summary Sheet - May 2026'!S10 -> 1667248 | U10: ='Summary Sheet - April 2026'!U10 -> 0 | W10: ='Summary Sheet - April 2026'!W10 + 'Summary Sheet - May 2026'!W10 -> 25283076 | Y10: ='Summary Sheet - April 2026'!Y10 -> 0 | AA10: ='Summary Sheet - April 2026'!AA10 + 'Summary Sheet - May 2026'!AA10 -> 19145660 | AC10: ='Summary Sheet - April 2026'!AC10 -> 0 | AE10: ='Summary Sheet - April 2026'!AE10 +'Summary Sheet - May 2026'!AE10 -> 34232739 | AG10: ='Summary Sheet - April 2026'!AG10 -> 0 | AI10: ='Summary Sheet - April 2026'!AI10 + 'Summary Sheet - May 2026'!AI10 -> 0 | AK10: ='Summary Sheet - April 2026'!AK10 -> 0 | AM10: ='Summary Sheet - April 2026'!AM10 + 'Summary Sheet - May 2026'!AM10 -> 970993.82 | AO10: ='Summary Sheet - April 2026'!AO10 -> 0 | AQ10: ='Summary Sheet - April 2026'!AQ10 + 'Summary Sheet - May 2026'!AQ10 -> 24146144 | AS10: ='Summary Sheet - April 2026'!AS10 -> 0 | AU10: ='Summary Sheet - April 2026'!AU10 + 'Summary Sheet - May 2026'!AU10 -> 666826.99 | AW10: =SUM(AW5:AW8) -> 0 | AY10: ='Summary Sheet - April 2026'!AY10 + 'Summary Sheet - May 2026'!AY10 -> 228077.89 | BA10: =SUM(BA5:BA8) -> 0 | BC10: =SUM(BC5:BC8) -> 306961.08 | BE10: =SUM(BE5:BE8) -> 0 | BG10: =SUM(BG5:BG8) -> 1236985 | BI10: =SUM(BI5:BI8) -> 0
B12: COGS | C12: =G12+K12 -> 55832434 | D12: =C12/$C$10 -> 0.37517005 | E12: =I12+M12 -> 0 | G12: ='Summary Sheet - April 2026'!G12 + 'Summary Sheet - May 2026'!G12 -> 0 | I12: ='Summary Sheet - April 2026'!I12 -> 0 | K12: =O12+S12+W12+AA12+AE12+AI12+AM12+AQ12+AU12+AY12+BC12+BG12 -> 55832434 | M12: =Q12+U12+Y12+AC12+AG12+AK12+AO12 -> 0 | O12: ='Summary Sheet - April 2026'!O12 +'Summary Sheet - May 2026'!O12 -> 14259873 | Q12: ='Summary Sheet - April 2026'!Q12 -> 0 | S12: ='Summary Sheet - April 2026'!S12 + 'Summary Sheet - May 2026'!S12 -> 573413.45 | U12: ='Summary Sheet - April 2026'!U12 -> 0 | W12: ='Summary Sheet - April 2026'!W12 + 'Summary Sheet - May 2026'!W12 -> 9869489.7 | Y12: ='Summary Sheet - April 2026'!Y12 -> 0 | AA12: ='Summary Sheet - April 2026'!AA12 + 'Summary Sheet - May 2026'!AA12 -> 6943290.1 | AC12: ='Summary Sheet - April 2026'!AC12 -> 0 | AE12: ='Summary Sheet - April 2026'!AE12 + 'Summary Sheet - May 2026'!AE12 -> 11423138 | AG12: ='Summary Sheet - April 2026'!AG12 -> 0 | AI12: ='Summary Sheet - April 2026'!AI12 + 'Summary Sheet - May 2026'!AI12 -> 0 | AK12: ='Summary Sheet - April 2026'!AK12 -> 0 | AM12: ='Summary Sheet - April 2026'!AM12 + 'Summary Sheet - May 2026'!AM12 -> 1697483.5 | AO12: ='Summary Sheet - April 2026'!AO12 -> 0 | AQ12: ='Summary Sheet - April 2026'!AQ12 + 'Summary Sheet - May 2026'!AQ12 -> 9435973 | AS12: ='Summary Sheet - April 2026'!AS12 -> 0 | AU12: ='Summary Sheet - April 2026'!AU12 + 'Summary Sheet - May 2026'!AU12 -> 438745.12 | AW12: ='Summary Sheet - April 2026'!AW12 -> 0 | AY12: ='Summary Sheet - April 2026'!AY12 + 'Summary Sheet - May 2026'!AY12 -> 339203.01 | BA12: ='Summary Sheet - April 2026'!BL12 -> 0 | BC12: ='Summary Sheet - April 2026'!BC12 + 'Summary Sheet - May 2026'!BC12 -> 495419.73 | BE12: ='Summary Sheet - April 2026'!BP12 -> 0 | BG12: ='Summary Sheet - April 2026'!BG12 + 'Summary Sheet - May 2026'!BG12 -> 356406.24 | BI12: ='Summary Sheet - April 2026'!BT12 -> 0
B13: Packaging Cost | C13: =G13+K13 -> 1899950.2 | D13: =C13/$C$10 -> 0.012766852 | E13: =I13+M13 -> 0 | G13: ='Summary Sheet - April 2026'!G13 + 'Summary Sheet - May 2026'!G13 -> 0 | I13: ='Summary Sheet - April 2026'!I13 -> 0 | K13: =O13+S13+W13+AA13+AE13+AI13+AM13+AQ13+AU13+AY13+BC13+BG13 -> 1899950.2 | M13: =Q13+U13+Y13+AC13+AG13+AK13+AO13 -> 0 | O13: ='Summary Sheet - April 2026'!O13 +'Summary Sheet - May 2026'!O13 -> 106548 | Q13: ='Summary Sheet - April 2026'!Q13 -> 0 | S13: ='Summary Sheet - April 2026'!S13 + 'Summary Sheet - May 2026'!S13 -> 73214 | U13: ='Summary Sheet - April 2026'!U13 -> 0 | W13: ='Summary Sheet - April 2026'!W13 + 'Summary Sheet - May 2026'!W13 -> 366401.4 | Y13: ='Summary Sheet - April 2026'!Y13 -> 0 | AA13: ='Summary Sheet - April 2026'!AA13 + 'Summary Sheet - May 2026'!AA13 -> 442124 | AC13: ='Summary Sheet - April 2026'!AC13 -> 0 | AE13: ='Summary Sheet - April 2026'!AE13 + 'Summary Sheet - May 2026'!AE13 -> 512245.02 | AG13: ='Summary Sheet - April 2026'!AG13 -> 0 | AI13: ='Summary Sheet - April 2026'!AI13 + 'Summary Sheet - May 2026'!AI13 -> 1030 | AK13: ='Summary Sheet - April 2026'!AK13 -> 0 | AM13: ='Summary Sheet - April 2026'!AM13 + 'Summary Sheet - May 2026'!AM13 -> 203076.5 | AO13: ='Summary Sheet - April 2026'!AO13 -> 0 | AQ13: ='Summary Sheet - April 2026'!AQ13 + 'Summary Sheet - May 2026'!AQ13 -> 85375.3 | AS13: ='Summary Sheet - April 2026'!AS13 -> 0 | AU13: ='Summary Sheet - April 2026'!AU13 + 'Summary Sheet - May 2026'!AU13 -> 8383 | AW13: ='Summary Sheet - April 2026'!AW13 -> 0 | AY13: ='Summary Sheet - April 2026'!AY13 + 'Summary Sheet - May 2026'!AY13 -> 9422 | BA13: ='Summary Sheet - April 2026'!BL13 -> 0 | BC13: ='Summary Sheet - April 2026'!BC13 + 'Summary Sheet - May 2026'!BC13 -> 5647 | BE13: ='Summary Sheet - April 2026'!BP13 -> 0 | BG13: ='Summary Sheet - April 2026'!BG13 + 'Summary Sheet - May 2026'!BG13 -> 86484 | BI13: ='Summary Sheet - April 2026'!BT13 -> 0
B14: Total COGS & Packaging | C14: =SUM(C12:C13) -> 57732384 | D14: =C14/C10 -> 0.3879369 | E14: =E12+E13 -> 0 | G14: =G12+G13 -> 0 | I14: ='Summary Sheet - April 2026'!I14 -> 0 | K14: =SUM(K12:K13) -> 57732384 | M14: =Q14+U14+Y14+AC14+AG14+AK14+AO14 -> 0 | O14: =O12+O13 -> 14366421 | Q14: ='Summary Sheet - April 2026'!Q14 -> 0 | S14: =S12+S13 -> 646627.45 | U14: ='Summary Sheet - April 2026'!U14 -> 0 | W14: =W12+W13 -> 10235891 | Y14: ='Summary Sheet - April 2026'!Y14 -> 0 | AA14: =AA12+AA13 -> 7385414.1 | AC14: ='Summary Sheet - April 2026'!AC14 -> 0 | AE14: =AE12+AE13 -> 11935383 | AG14: ='Summary Sheet - April 2026'!AG14 -> 0 | AI14: =AI12+AI13 -> 1030 | AK14: =AK12+AK13 -> 0 | AM14: =AM12+AM13 -> 1900560 | AO14: =AO12+AO13 -> 0 | AQ14: =AQ12+AQ13 -> 9521348.3 | AS14: =AS12+AS13 -> 0 | AU14: =AU12+AU13 -> 447128.12 | AW14: =AW12+AW13 -> 0 | AY14: =AY12+AY13 -> 348625.01 | BA14: =BA12+BA13 -> 0 | BC14: =BC12+BC13 -> 501066.73 | BE14: =BE12+BE13 -> 0 | BG14: =BG12+BG13 -> 442890.24 | BI14: =BI12+BI13 -> 0
B15: DEQ
B16: Gross Margin | C16: =C10-C14 -> 91086622 | D16: =C16/C10 -> 0.6120631 | E16: =E10-E14 -> 0 | G16: =G10-G14 -> 0 | I16: =I10-I14 -> 0 | K16: =K10-K14 -> 91086622 | M16: =M10-M14 -> 0 | O16: =O10-O14-O15 -> 26567872 | Q16: =Q10-Q14-Q15 -> 0 | S16: =S10-S14-S15 -> 1020620.5 | U16: =U10-U14-U15 -> 0 | W16: =W10-W14-W15 -> 15047185 | Y16: =Y10-Y14-Y15 -> 0 | AA16: =AA10-AA14-AA15 -> 11760246 | AC16: =AC10-AC14-AC15 -> 0 | AE16: =AE10-AE14-AE15 -> 22297357 | AG16: =AG10-AG14-AG15 -> 0 | AI16: =AI10-AI14-AI15 -> -1030 | AK16: ='Summary Sheet - April 2026'!AK17 -> 0 | AM16: =AM10-AM14-AM15 -> -929566.16 | AO16: ='Summary Sheet - April 2026'!AO17 -> 0 | AQ16: =AQ10-AQ14-AQ15 -> 14624796 | AS16: ='Summary Sheet - April 2026'!AS17 -> 0 | AU16: =AU10-AU14-AU15 -> 219698.87 | AW16: =AW10-AW14 -> 0 | AY16: =AY10-AY14-AY15 -> -120547.12 | BA16: =BA10-BA14 -> 0 | BC16: =BC10-BC14-BC15 -> -194105.65 | BE16: =BE10-BE14 -> 0 | BG16: =BG10-BG14-BG15 -> 794094.76 | BI16: =BI10-BI14 -> 0
B18: Other Direct Expenses | C18: =G18+K18 -> 3971287.5 | D18: =C18/$C$10 -> 0.026685352 | E18: =I18+M18 -> 0 | G18: ='Summary Sheet - April 2026'!G19 + 'Summary Sheet - May 2026'!G19 -> 128002.51 | I18: ='Summary Sheet - April 2026'!I19 -> 0 | K18: =O18+S18+W18+AA18+AE18+AI18+AM18+AQ18+AU18+AY18+BC18+BG18 -> 3843285 | M18: =Q18+U18+Y18+AC18+AG18+AK18+AO18 -> 0 | O18: ='Summary Sheet - April 2026'!O19 + 'Summary Sheet - May 2026'!O19 -> 949580.56 | Q18: ='Summary Sheet - April 2026'!Q19 -> 0 | S18: ='Summary Sheet - April 2026'!S19 +'Summary Sheet - May 2026'!S19 -> 91280.29 | U18: ='Summary Sheet - April 2026'!U19 -> 0 | W18: ='Summary Sheet - April 2026'!W19 + 'Summary Sheet - May 2026'!W19 -> 750009.87 | Y18: ='Summary Sheet - April 2026'!Y19 -> 0 | AA18: ='Summary Sheet - April 2026'!AA19 + 'Summary Sheet - May 2026'!AA19 -> 483204.82 | AC18: ='Summary Sheet - April 2026'!AC19 -> 0 | AE18: ='Summary Sheet - April 2026'!AE19 + 'Summary Sheet - May 2026'!AE19 -> 989178.45 | AG18: ='Summary Sheet - April 2026'!AG19 -> 0 | AI18: ='Summary Sheet - April 2026'!AI19 + 'Summary Sheet - May 2026'!AI19 -> 35514 | AK18: ='Summary Sheet - April 2026'!AK19 -> 0 | AM18: ='Summary Sheet - April 2026'!AM19 + 'Summary Sheet - May 2026'!AM19 -> 71198.86 | AO18: ='Summary Sheet - April 2026'!AO19 -> 0 | AQ18: ='Summary Sheet - April 2026'!AQ19 + 'Summary Sheet - May 2026'!AQ19 -> 467605.13 | AS18: ='Summary Sheet - April 2026'!AS19 -> 0 | AU18: ='Summary Sheet - April 2026'!AU19 + 'Summary Sheet - May 2026'!AU19 -> 0 | AW18: ='Summary Sheet - April 2026'!AW19 -> 0 | AY18: ='Summary Sheet - April 2026'!AY19 + 'Summary Sheet - May 2026'!AY19 -> 0 | BA18: ='Summary Sheet - April 2026'!BL19 -> 0 | BC18: ='Summary Sheet - April 2026'!BC19 + 'Summary Sheet - May 2026'!BC19 -> 0 | BE18: ='Summary Sheet - April 2026'!BP19 -> 0 | BG18: ='Summary Sheet - April 2026'!BG19 + 'Summary Sheet - May 2026'!BG19 -> 5713 | BI18: ='Summary Sheet - April 2026'!BT19 -> 0
